Workbook

Sheet Sheet1
A1: case_id | B1: qc_status | C1: qc_reason | D1: meal_date | E1: meal_datetime | F1: venous_glu | G1: G0 | H1: G15 | I1: G30 | J1: G45 | K1: G60 | L1: G75 | M1: G90 | N1: G105 | O1: G120 | P1: G135 | Q1: G150 | R1: G165 | S1: G180 | T1: G_peak | U1: T_baseline2peak_min | V1: S_baseline_peak | W1: S_peak_end | X1: AUC_0_180 | Y1: pAUC | Z1: nAUC | AA1: iAUC | AB1: CGM1_time | AC1: CGM1_value | AD1: CGM2_time | AE1: CGM2_value | AF1: CGM3_time | AG1: CGM3_value | AH1: CGM4_time | AI1: CGM4_value | AJ1: CGM5_time | AK1: CGM5_value | AL1: CGM6_time | AM1: CGM6_value | AN1: CGM7_time | AO1: CGM7_value | AP1: CGM8_time | AQ1: CGM8_value | AR1: CGM9_time | AS1: CGM9_value | AT1: CGM10_time | AU1: CGM10_value | AV1: CGM11_time | AW1: CGM11_value | AX1: CGM12_time | AY1: CGM12_value | AZ1: CGM13_time | BA1: CGM13_value | BB1: CGM14_time | BC1: CGM14_value | BD1: CGM15_time | BE1: CGM15_value | BF1: CGM16_time | BG1: CGM16_value | BH1: CGM17_time | BI1: CGM17_value | BJ1: CGM18_time | BK1: CGM18_value | BL1: CGM19_time | BM1: CGM19_value | BN1: CGM20_time | BO1: CGM20_value | BP1: CGM21_time | BQ1: CGM21_value | BR1: CGM22_time | BS1: CGM22_value | BT1: CGM23_time | BU1: CGM23_value | BW1: 1 | BX1: 2 | BY1: 3 | BZ1: 4 | CA1: 5 | CB1: 6 | CC1: 7 | CD1: 8 | CE1: 9 | CF1: 10 | CG1: 11 | CH1: 12 | CI1: 13 | CJ1: 14 | CK1: 15 | CL1: 16 | CM1: 17 | CN1: 18 | CO1: 19 | CP1: 20 | CQ1: 21 | CR1: 22 | CS1: 23
A2: 129449 | B2: 正常 | D2: 45355 | E2: 45355.292 | F2: 7.99 | G2: 5.5 | H2: 5.74 | I2: 5.7 | J2: 5.7 | K2: 5.7 | L2: 5.76 | M2: 6.1 | N2: 6.66 | O2: 7.08 | P2: 7.32 | Q2: 7.64 | R2: 7.86 | S2: 7.9 | T2: 7.9 | U2: 171 | V2: 0.014035088 | W2: 0 | X2: 1169.4 | Y2: 0 | Z2: 1169.4 | AA2: -1169.4 | AB2: 45355.275 | AC2: 5.4 | AD2: 45355.285 | AE2: 5.6 | AF2: 45355.296 | AG2: 5.8 | AH2: 45355.306 | AI2: 5.7 | AJ2: 45355.317 | AK2: 5.7 | AL2: 45355.327 | AM2: 5.7 | AN2: 45355.338 | AO2: 5.7 | AP2: 45355.348 | AQ2: 5.8 | AR2: 45355.358 | AS2: 6.3 | AT2: 45355.369 | AU2: 6.9 | AV2: 45355.379 | AW2: 7.2 | AX2: 45355.39 | AY2: 7.4 | AZ2: 45355.4 | BA2: 7.8 | BB2: 45355.41 | BC2: 7.9 | BD2: 45355.421 | BE2: 7.6 | BF2: 45355.431 | BG2: 7.4 | BH2: 45355.442 | BI2: 7.3 | BJ2: 45355.452 | BK2: 7.5 | BL2: 45355.463 | BM2: 7.4 | BN2: 45355.473 | BO2: 7 | BP2: 45355.483 | BQ2: 6.4 | BR2: 45355.494 | BS2: 6.2 | BT2: 45355.504 | BU2: 6.1 | BW2: {=INDEX($AC2:$BU2, 2*(COLUMN(BV2)-COLUMN($BV2))+1)} -> 5.4 | BX2: {=INDEX($AC2:$BU2, 2*(COLUMN(BW2)-COLUMN($BV2))+1)} -> 5.6 | BY2: {=INDEX($AC2:$BU2, 2*(COLUMN(BX2)-COLUMN($BV2))+1)} -> 5.8 | BZ2: {=INDEX($AC2:$BU2, 2*(COLUMN(BY2)-COLUMN($BV2))+1)} -> 5.7 | CA2: {=INDEX($AC2:$BU2, 2*(COLUMN(BZ2)-COLUMN($BV2))+1)} -> 5.7 | CB2: {=INDEX($AC2:$BU2, 2*(COLUMN(CA2)-COLUMN($BV2))+1)} -> 5.7 | CC2: {=INDEX($AC2:$BU2, 2*(COLUMN(CB2)-COLUMN($BV2))+1)} -> 5.7 | CD2: {=INDEX($AC2:$BU2, 2*(COLUMN(CC2)-COLUMN($BV2))+1)} -> 5.8 | ... CS2: {=INDEX($AC2:$BU2, 2*(COLUMN(CR2)-COLUMN($BV2))+1)} -> 6.1
A3: 156334 | B3: 正常 | D3: 44999 | E3: 44999.292 | F3: 9.26 | G3: 8.6 | H3: 8.9 | I3: 9 | J3: 9 | K3: 9 | L3: 8.8666667 | M3: 8.8 | N3: 8.7333333 | O3: 8.5 | P3: 8.5333333 | Q3: 8.7333333 | R3: 8.4 | S3: 8.2 | T3: 9 | U3: 20 | V3: 0.02 | W3: -0.005 | X3: 1573 | Y3: 0 | Z3: 1573 | AA3: -1573 | AB3: 44999.274 | AC3: 8.7 | AD3: 44999.285 | AE3: 8.5 | AF3: 44999.295 | AG3: 8.7 | AH3: 44999.306 | AI3: 9 | AJ3: 44999.316 | AK3: 9 | AL3: 44999.326 | AM3: 9 | AN3: 44999.337 | AO3: 9 | AP3: 44999.347 | AQ3: 8.8 | AR3: 44999.358 | AS3: 8.8 | AT3: 44999.368 | AU3: 8.7 | AV3: 44999.378 | AW3: 8.4 | AX3: 44999.389 | AY3: 8.6 | AZ3: 44999.399 | BA3: 8.8 | BB3: 44999.41 | BC3: 8.2 | BD3: 44999.42 | BE3: 7.6 | BF3: 44999.431 | BG3: 7.3 | BH3: 44999.441 | BI3: 7.3 | BJ3: 44999.451 | BK3: 7.1 | BL3: 44999.462 | BM3: 6.9 | BN3: 44999.472 | BO3: 6.8 | BP3: 44999.483 | BQ3: 6.7 | BR3: 44999.493 | BS3: 6.6 | BT3: 44999.503 | BU3: 6.6 | BW3: {=INDEX($AC3:$BU3, 2*(COLUMN(BV3)-COLUMN($BV3))+1)} -> 8.7 | BX3: {=INDEX($AC3:$BU3, 2*(COLUMN(BW3)-COLUMN($BV3))+1)} -> 8.5 | BY3: {=INDEX($AC3:$BU3, 2*(COLUMN(BX3)-COLUMN($BV3))+1)} -> 8.7 | BZ3: {=INDEX($AC3:$BU3, 2*(COLUMN(BY3)-COLUMN($BV3))+1)} -> 9 | CA3: {=INDEX($AC3:$BU3, 2*(COLUMN(BZ3)-COLUMN($BV3))+1)} -> 9 | CB3: {=INDEX($AC3:$BU3, 2*(COLUMN(CA3)-COLUMN($BV3))+1)} -> 9 | CC3: {=INDEX($AC3:$BU3, 2*(COLUMN(CB3)-COLUMN($BV3))+1)} -> 9 | CD3: {=INDEX($AC3:$BU3, 2*(COLUMN(CC3)-COLUMN($BV3))+1)} -> 8.8 | ... CS3: {=INDEX($AC3:$BU3, 2*(COLUMN(CR3)-COLUMN($BV3))+1)} -> 6.6
A4: 147337 | B4: 正常 | D4: 45302 | E4: 45302.292 | F4: 7.8696429 | G4: 6.9 | H4: 6.64 | I4: 6.28 | J4: 5.98 | K4: 5.92 | L4: 6.74 | M4: 8.78 | N4: 11.08 | O4: 11.94 | P4: 11.46 | Q4: 11.1 | R4: 11.02 | S4: 10.9 | T4: 12.1 | U4: 114 | V4: 0.045614035 | W4: -0.018181818 | X4: 1587.6 | Y4: 0 | Z4: 1587.6 | AA4: -1587.6 | AB4: 45302.277 | AC4: 6.8 | AD4: 45302.287 | AE4: 7 | AF4: 45302.298 | AG4: 6.8 | AH4: 45302.308 | AI4: 6.4 | AJ4: 45302.319 | AK4: 6.1 | AL4: 45302.329 | AM4: 5.8 | AN4: 45302.34 | AO4: 6.1 | AP4: 45302.35 | AQ4: 7.7 | AR4: 45302.36 | AS4: 10.4 | AT4: 45302.371 | AU4: 12.1 | AV4: 45302.381 | AW4: 11.7 | AX4: 45302.392 | AY4: 11.1 | AZ4: 45302.402 | BA4: 11.1 | BB4: 45302.412 | BC4: 10.9 | BD4: 45302.423 | BE4: 10.5 | BF4: 45302.433 | BG4: 10.2 | BH4: 45302.444 | BI4: 9.5 | BJ4: 45302.454 | BK4: 8.3 | BL4: 45302.465 | BM4: 7.4 | BN4: 45302.475 | BO4: 7.1 | BP4: 45302.485 | BQ4: 6.7 | BR4: 45302.496 | BS4: 6.5 | BT4: 45302.506 | BU4: 6.8 | BW4: {=INDEX($AC4:$BU4, 2*(COLUMN(BV4)-COLUMN($BV4))+1)} -> 6.8 | BX4: {=INDEX($AC4:$BU4, 2*(COLUMN(BW4)-COLUMN($BV4))+1)} -> 7 | BY4: {=INDEX($AC4:$BU4, 2*(COLUMN(BX4)-COLUMN($BV4))+1)} -> 6.8 | BZ4: {=INDEX($AC4:$BU4, 2*(COLUMN(BY4)-COLUMN($BV4))+1)} -> 6.4 | CA4: {=INDEX($AC4:$BU4, 2*(COLUMN(BZ4)-COLUMN($BV4))+1)} -> 6.1 | CB4: {=INDEX($AC4:$BU4, 2*(COLUMN(CA4)-COLUMN($BV4))+1)} -> 5.8 | CC4: {=INDEX($AC4:$BU4, 2*(COLUMN(CB4)-COLUMN($BV4))+1)} -> 6.1 | CD4: {=INDEX($AC4:$BU4, 2*(COLUMN(CC4)-COLUMN($BV4))+1)} -> 7.7 | ... CS4: {=INDEX($AC4:$BU4, 2*(COLUMN(CR4)-COLUMN($BV4))+1)} -> 6.8
A5: 129464 | B5: 正常 | D5: 45385 | E5: 45385.292 | F5: 9.528665 | G5: 9.8 | H5: 10.273333 | I5: 10.213333 | J5: 9.94 | K5: 9.38 | L5: 8.78 | M5: 8.96 | N5: 10.04 | O5: 11.066667 | P5: 11.373333 | Q5: 11.053333 | R5: 10.653333 | S5: 10.6 | T5: 11.4 | U5: 137 | V5: 0.011678832 | W5: -0.018604651 | X5: 1829 | Y5: 0 | Z5: 1829 | AA5: -1829 | AB5: 45385.272 | AC5: 9.7 | AD5: 45385.283 | AE5: 9.9 | AF5: 45385.293 | AG5: 10.1 | AH5: 45385.303 | AI5: 10.3 | AJ5: 45385.314 | AK5: 10.2 | AL5: 45385.324 | AM5: 9.9 | AN5: 45385.335 | AO5: 9.3 | AP5: 45385.345 | AQ5: 8.7 | AR5: 45385.356 | AS5: 9 | AT5: 45385.366 | AU5: 10.2 | AV5: 45385.376 | AW5: 11.2 | AX5: 45385.387 | AY5: 11.4 | AZ5: 45385.397 | BA5: 11 | BB5: 45385.408 | BC5: 10.6 | BD5: 45385.418 | BE5: 10.3 | BF5: 45385.428 | BG5: 10.1 | BH5: 45385.439 | BI5: 10.2 | BJ5: 45385.449 | BK5: 10.2 | BL5: 45385.46 | BM5: 9.6 | BN5: 45385.47 | BO5: 8.2 | BP5: 45385.481 | BQ5: 7.1 | BR5: 45385.491 | BS5: 7.2 | BT5: 45385.501 | BU5: 7.5 | BW5: {=INDEX($AC5:$BU5, 2*(COLUMN(BV5)-COLUMN($BV5))+1)} -> 9.7 | BX5: {=INDEX($AC5:$BU5, 2*(COLUMN(BW5)-COLUMN($BV5))+1)} -> 9.9 | BY5: {=INDEX($AC5:$BU5, 2*(COLUMN(BX5)-COLUMN($BV5))+1)} -> 10.1 | BZ5: {=INDEX($AC5:$BU5, 2*(COLUMN(BY5)-COLUMN($BV5))+1)} -> 10.3 | CA5: {=INDEX($AC5:$BU5, 2*(COLUMN(BZ5)-COLUMN($BV5))+1)} -> 10.2 | CB5: {=INDEX($AC5:$BU5, 2*(COLUMN(CA5)-COLUMN($BV5))+1)} -> 9.9 | CC5: {=INDEX($AC5:$BU5, 2*(COLUMN(CB5)-COLUMN($BV5))+1)} -> 9.3 | CD5: {=INDEX($AC5:$BU5, 2*(COLUMN(CC5)-COLUMN($BV5))+1)} -> 8.7 | ... CS5: {=INDEX($AC5:$BU5, 2*(COLUMN(CR5)-COLUMN($BV5))+1)} -> 7.5
A6: 159819 | B6: 正常 | D6: 45072 | E6: 45072.292 | F6: 10.391588 | G6: 8.05 | H6: 9.26 | I6: 9.5066667 | J6: 9.4933333 | K6: 9.3466667 | L6: 9.46 | M6: 9.5466667 | N6: 9.2866667 | O6: 9.1 | P6: 9.2066667 | Q6: 9.3533333 | R6: 9.6133333 | S6: 9.8 | T6: 9.8 | U6: 172 | V6: 0.010174419 | W6: 0 | X6: 1681.475 | Y6: 0 | Z6: 1681.475 | AA6: -1681.475 | AB6: 45072.276 | AC6: 7.7 | AD6: 45072.286 | AE6: 8.4 | AF6: 45072.297 | AG6: 9.1 | AH6: 45072.307 | AI6: 9.4 | AJ6: 45072.317 | AK6: 9.6 | AL6: 45072.328 | AM6: 9.4 | AN6: 45072.338 | AO6: 9.3 | AP6: 45072.349 | AQ6: 9.6 | AR6: 45072.359 | AS6: 9.5 | AT6: 45072.369 | AU6: 9.1 | AV6: 45072.38 | AW6: 9.1 | AX6: 45072.39 | AY6: 9.3 | AZ6: 45072.401 | BA6: 9.4 | BB6: 45072.411 | BC6: 9.8 | BD6: 45072.422 | BE6: 10.3 | BF6: 45072.432 | BG6: 10 | BH6: 45072.442 | BI6: 9.7 | BJ6: 45072.453 | BK6: 9.8 | BL6: 45072.463 | BM6: 9.7 | BN6: 45072.474 | BO6: 9.8 | BP6: 45072.484 | BQ6: 10.1 | BR6: 45072.494 | BS6: 10.7 | BT6: 45072.505 | BU6: 10.8 | BW6: {=INDEX($AC6:$BU6, 2*(COLUMN(BV6)-COLUMN($BV6))+1)} -> 7.7 | BX6: {=INDEX($AC6:$BU6, 2*(COLUMN(BW6)-COLUMN($BV6))+1)} -> 8.4 | BY6: {=INDEX($AC6:$BU6, 2*(COLUMN(BX6)-COLUMN($BV6))+1)} -> 9.1 | BZ6: {=INDEX($AC6:$BU6, 2*(COLUMN(BY6)-COLUMN($BV6))+1)} -> 9.4 | CA6: {=INDEX($AC6:$BU6, 2*(COLUMN(BZ6)-COLUMN($BV6))+1)} -> 9.6 | CB6: {=INDEX($AC6:$BU6, 2*(COLUMN(CA6)-COLUMN($BV6))+1)} -> 9.4 | CC6: {=INDEX($AC6:$BU6, 2*(COLUMN(CB6)-COLUMN($BV6))+1)} -> 9.3 | CD6: {=INDEX($AC6:$BU6, 2*(COLUMN(CC6)-COLUMN($BV6))+1)} -> 9.6 | ... CS6: {=INDEX($AC6:$BU6, 2*(COLUMN(CR6)-COLUMN($BV6))+1)} -> 10.8
A7: 172029 | B7: 正常 | D7: 45273 | E7: 45273.292 | F7: 12.433629 | G7: 10.75 | H7: 9.7266667 | I7: 9.0666667 | J7: 8.8466667 | K7: 8.8533333 | L7: 8.8466667 | M7: 9.5066667 | N7: 11.04 | O7: 12.28 | P7: 12.366667 | Q7: 11.866667 | R7: 11.32 | S7: 11 | T7: 12.6 | U7: 128 | V7: 0.014453125 | W7: -0.030769231 | X7: 1868.925 | Y7: 0 | Z7: 1868.925 | AA7: -1868.925 | AB7: 45273.276 | AC7: 11.1 | AD7: 45273.287 | AE7: 10.4 | AF7: 45273.297 | AG7: 10.1 | AH7: 45273.308 | AI7: 9.3 | AJ7: 45273.318 | AK7: 8.8 | AL7: 45273.328 | AM7: 8.9 | AN7: 45273.339 | AO7: 8.8 | AP7: 45273.349 | AQ7: 8.9 | AR7: 45273.36 | AS7: 10.2 | AT7: 45273.37 | AU7: 12 | AV7: 45273.381 | AW7: 12.6 | AX7: 45273.391 | AY7: 12.1 | AZ7: 45273.401 | BA7: 11.6 | BB7: 45273.412 | BC7: 11 | BD7: 45273.422 | BE7: 10.6 | BF7: 45273.433 | BG7: 10.9 | BH7: 45273.443 | BI7: 10.5 | BJ7: 45273.453 | BK7: 9.9 | BL7: 45273.464 | BM7: 9.7 | BN7: 45273.474 | BO7: 9.6 | BP7: 45273.485 | BQ7: 9.8 | BR7: 45273.495 | BS7: 9.8 | BT7: 45273.506 | BU7: 10.2 | BW7: {=INDEX($AC7:$BU7, 2*(COLUMN(BV7)-COLUMN($BV7))+1)} -> 11.1 | BX7: {=INDEX($AC7:$BU7, 2*(COLUMN(BW7)-COLUMN($BV7))+1)} -> 10.4 | BY7: {=INDEX($AC7:$BU7, 2*(COLUMN(BX7)-COLUMN($BV7))+1)} -> 10.1 | BZ7: {=INDEX($AC7:$BU7, 2*(COLUMN(BY7)-COLUMN($BV7))+1)} -> 9.3 | CA7: {=INDEX($AC7:$BU7, 2*(COLUMN(BZ7)-COLUMN($BV7))+1)} -> 8.8 | CB7: {=INDEX($AC7:$BU7, 2*(COLUMN(CA7)-COLUMN($BV7))+1)} -> 8.9 | CC7: {=INDEX($AC7:$BU7, 2*(COLUMN(CB7)-COLUMN($BV7))+1)} -> 8.8 | CD7: {=INDEX($AC7:$BU7, 2*(COLUMN(CC7)-COLUMN($BV7))+1)} -> 8.9 | ... CS7: {=INDEX($AC7:$BU7, 2*(COLUMN(CR7)-COLUMN($BV7))+1)} -> 10.2
A8: 180732 | B8: 正常 | D8: 45378 | E8: 45378.292 | F8: 10.603413 | G8: 10.4 | H8: 10.1 | I8: 10.1 | J8: 10.1 | K8: 10.186667 | L8: 10.373333 | M8: 10.66 | N8: 10.873333 | O8: 10.64 | P8: 10.513333 | Q8: 10.326667 | R8: 9.78 | S8: 9.7 | T8: 10.9 | U8: 107 | V8: 0.0046728972 | W8: -0.016438356 | X8: 1855.55 | Y8: 0 | Z8: 1855.55 | AA8: -1855.55 | AB8: 45378.272 | AC8: 10.5 | AD8: 45378.283 | AE8: 10.3 | AF8: 45378.293 | AG8: 10.1 | AH8: 45378.303 | AI8: 10.1 | AJ8: 45378.314 | AK8: 10.1 | AL8: 45378.324 | AM8: 10.1 | AN8: 45378.335 | AO8: 10.2 | AP8: 45378.345 | AQ8: 10.4 | AR8: 45378.356 | AS8: 10.7 | AT8: 45378.366 | AU8: 10.9 | AV8: 45378.376 | AW8: 10.6 | AX8: 45378.387 | AY8: 10.5 | AZ8: 45378.397 | BA8: 10.3 | BB8: 45378.408 | BC8: 9.7 | BD8: 45378.418 | BE8: 9.6 | BF8: 45378.428 | BG8: 10.2 | BH8: 45378.439 | BI8: 10.6 | BJ8: 45378.449 | BK8: 10.8 | BL8: 45378.46 | BM8: 10.5 | BN8: 45378.47 | BO8: 10.3 | BP8: 45378.481 | BQ8: 10.3 | BR8: 45378.491 | BS8: 10.2 | BT8: 45378.501 | BU8: 10.1 | BW8: {=INDEX($AC8:$BU8, 2*(COLUMN(BV8)-COLUMN($BV8))+1)} -> 10.5 | BX8: {=INDEX($AC8:$BU8, 2*(COLUMN(BW8)-COLUMN($BV8))+1)} -> 10.3 | BY8: {=INDEX($AC8:$BU8, 2*(COLUMN(BX8)-COLUMN($BV8))+1)} -> 10.1 | BZ8: {=INDEX($AC8:$BU8, 2*(COLUMN(BY8)-COLUMN($BV8))+1)} -> 10.1 | CA8: {=INDEX($AC8:$BU8, 2*(COLUMN(BZ8)-COLUMN($BV8))+1)} -> 10.1 | CB8: {=INDEX($AC8:$BU8, 2*(COLUMN(CA8)-COLUMN($BV8))+1)} -> 10.1 | CC8: {=INDEX($AC8:$BU8, 2*(COLUMN(CB8)-COLUMN($BV8))+1)} -> 10.2 | CD8: {=INDEX($AC8:$BU8, 2*(COLUMN(CC8)-COLUMN($BV8))+1)} -> 10.4 | ... CS8: {=INDEX($AC8:$BU8, 2*(COLUMN(CR8)-COLUMN($BV8))+1)} -> 10.1
A9: 185715 | B9: 正常 | D9: 45113 | E9: 45113.292 | F9: 8.47 | G9: 6.4 | H9: 6.6 | I9: 6.68 | J9: 7.1 | K9: 7.44 | L9: 7.34 | M9: 7.3 | N9: 7.54 | O9: 7.84 | P9: 7.74 | Q9: 7.46 | R9: 7.72 | S9: 7.8 | T9: 7.9 | U9: 123 | V9: 0.012195122 | W9: -0.001754386 | X9: 1317.9 | Y9: 0 | Z9: 1317.9 | AA9: -1317.9 | AB9: 45113.273 | AC9: 6.4 | AD9: 45113.283 | AE9: 6.4 | AF9: 45113.294 | AG9: 6.6 | AH9: 45113.304 | AI9: 6.6 | AJ9: 45113.315 | AK9: 6.7 | AL9: 45113.325 | AM9: 7.2 | AN9: 45113.335 | AO9: 7.5 | AP9: 45113.346 | AQ9: 7.3 | AR9: 45113.356 | AS9: 7.3 | AT9: 45113.367 | AU9: 7.6 | AV9: 45113.377 | AW9: 7.9 | AX9: 45113.387 | AY9: 7.7 | AZ9: 45113.398 | BA9: 7.4 | BB9: 45113.408 | BC9: 7.8 | BD9: 45113.419 | BE9: 8.1 | BF9: 45113.429 | BG9: 7.8 | BH9: 45113.44 | BI9: 7.8 | BJ9: 45113.45 | BK9: 7.6 | BL9: 45113.46 | BM9: 7 | BN9: 45113.471 | BO9: 6.9 | BP9: 45113.481 | BQ9: 7.1 | BR9: 45113.492 | BS9: 7.3 | BT9: 45113.502 | BU9: 7.1 | BW9: {=INDEX($AC9:$BU9, 2*(COLUMN(BV9)-COLUMN($BV9))+1)} -> 6.4 | BX9: {=INDEX($AC9:$BU9, 2*(COLUMN(BW9)-COLUMN($BV9))+1)} -> 6.4 | BY9: {=INDEX($AC9:$BU9, 2*(COLUMN(BX9)-COLUMN($BV9))+1)} -> 6.6 | BZ9: {=INDEX($AC9:$BU9, 2*(COLUMN(BY9)-COLUMN($BV9))+1)} -> 6.6 | CA9: {=INDEX($AC9:$BU9, 2*(COLUMN(BZ9)-COLUMN($BV9))+1)} -> 6.7 | CB9: {=INDEX($AC9:$BU9, 2*(COLUMN(CA9)-COLUMN($BV9))+1)} -> 7.2 | CC9: {=INDEX($AC9:$BU9, 2*(COLUMN(CB9)-COLUMN($BV9))+1)} -> 7.5 | CD9: {=INDEX($AC9:$BU9, 2*(COLUMN(CC9)-COLUMN($BV9))+1)} -> 7.3 | ... CS9: {=INDEX($AC9:$BU9, 2*(COLUMN(CR9)-COLUMN($BV9))+1)} -> 7.1
A10: 187123 | B10: 正常 | D10: 45314 | E10: 45314.292 | F10: 10.65 | G10: 10.05 | H10: 10.38 | I10: 10.4 | J10: 10.72 | K10: 10.8 | L10: 10.48 | M10: 10.08 | N10: 10 | O10: 10.16 | P10: 10.12 | Q10: 9.86 | R10: 9.72 | S10: 9.7 | T10: 10.8 | U10: 48 | V10: 0.015625 | W10: -0.0083333333 | X10: 1838.925 | Y10: 0 | Z10: 1838.925 | AA10: -1838.925 | AB10: 45314.273 | AC10: 9.9 | AD10: 45314.283 | AE10: 10.2 | AF10: 45314.294 | AG10: 10.3 | AH10: 45314.304 | AI10: 10.4 | AJ10: 45314.315 | AK10: 10.4 | AL10: 45314.325 | AM10: 10.8 | AN10: 45314.335 | AO10: 10.8 | AP10: 45314.346 | AQ10: 10.4 | AR10: 45314.356 | AS10: 10 | AT10: 45314.367 | AU10: 10 | AV10: 45314.377 | AW10: 10.2 | AX10: 45314.387 | AY10: 10.1 | AZ10: 45314.398 | BA10: 9.8 | BB10: 45314.408 | BC10: 9.7 | BD10: 45314.419 | BE10: 9.3 | BF10: 45314.429 | BG10: 9.2 | BH10: 45314.44 | BI10: 9.5 | BJ10: 45314.45 | BK10: 9.8 | BL10: 45314.46 | BM10: 10 | BN10: 45314.471 | BO10: 10.2 | BP10: 45314.481 | BQ10: 10.8 | BR10: 45314.492 | BS10: 11.5 | BT10: 45314.502 | BU10: 11.8 | BW10: {=INDEX($AC10:$BU10, 2*(COLUMN(BV10)-COLUMN($BV10))+1)} -> 9.9 | BX10: {=INDEX($AC10:$BU10, 2*(COLUMN(BW10)-COLUMN($BV10))+1)} -> 10.2 | BY10: {=INDEX($AC10:$BU10, 2*(COLUMN(BX10)-COLUMN($BV10))+1)} -> 10.3 | BZ10: {=INDEX($AC10:$BU10, 2*(COLUMN(BY10)-COLUMN($BV10))+1)} -> 10.4 | CA10: {=INDEX($AC10:$BU10, 2*(COLUMN(BZ10)-COLUMN($BV10))+1)} -> 10.4 | CB10: {=INDEX($AC10:$BU10, 2*(COLUMN(CA10)-COLUMN($BV10))+1)} -> 10.8 | CC10: {=INDEX($AC10:$BU10, 2*(COLUMN(CB10)-COLUMN($BV10))+1)} -> 10.8 | CD10: {=INDEX($AC10:$BU10, 2*(COLUMN(CC10)-COLUMN($BV10))+1)} -> 10.4 | ... CS10: {=INDEX($AC10:$BU10, 2*(COLUMN(CR10)-COLUMN($BV10))+1)} -> 11.8
A11: 189328 | B11: 正常 | D11: 45005 | E11: 45005.292 | F11: 14.948517 | G11: 13.65 | H11: 15.9 | I11: 17.733333 | J11: 19.533333 | K11: 21 | L11: 21.9 | M11: 21.9 | N11: 21.366667 | O11: 21 | P11: 20.533333 | Q11: 19.733333 | R11: 19.033333 | S11: 18.7 | T11: 22.1 | U11: 85 | V11: 0.099411765 | W11: -0.035789474 | X11: 3537.125 | Y11: 0 | Z11: 3537.125 | AA11: -3537.125 | AB11: 45005.278 | AC11: 13.4 | AD11: 45005.288 | AE11: 13.9 | AF11: 45005.299 | AG11: 15.3 | AH11: 45005.309 | AI11: 17.1 | AJ11: 45005.319 | AK11: 19 | AL11: 45005.33 | AM11: 20.6 | AN11: 45005.34 | AO11: 21.8 | AP11: 45005.351 | AQ11: 22.1 | AR11: 45005.361 | AS11: 21.5 | AT11: 45005.372 | AU11: 21.1 | AV11: 45005.382 | AW11: 20.8 | AX11: 45005.392 | AY11: 20 | AZ11: 45005.403 | BA11: 19.2 | BB11: 45005.413 | BC11: 18.7 | BD11: 45005.424 | BE11: 18 | BF11: 45005.434 | BG11: 17.2 | BH11: 45005.444 | BI11: 16.8 | BJ11: 45005.455 | BK11: 16.8 | BL11: 45005.465 | BM11: 16.4 | BN11: 45005.476 | BO11: 15.6 | BP11: 45005.486 | BQ11: 15.3 | BR11: 45005.497 | BS11: 15.8 | BT11: 45005.507 | BU11: 16.7 | BW11: {=INDEX($AC11:$BU11, 2*(COLUMN(BV11)-COLUMN($BV11))+1)} -> 13.4 | BX11: {=INDEX($AC11:$BU11, 2*(COLUMN(BW11)-COLUMN($BV11))+1)} -> 13.9 | BY11: {=INDEX($AC11:$BU11, 2*(COLUMN(BX11)-COLUMN($BV11))+1)} -> 15.3 | BZ11: {=INDEX($AC11:$BU11, 2*(COLUMN(BY11)-COLUMN($BV11))+1)} -> 17.1 | CA11: {=INDEX($AC11:$BU11, 2*(COLUMN(BZ11)-COLUMN($BV11))+1)} -> 19 | CB11: {=INDEX($AC11:$BU11, 2*(COLUMN(CA11)-COLUMN($BV11))+1)} -> 20.6 | CC11: {=INDEX($AC11:$BU11, 2*(COLUMN(CB11)-COLUMN($BV11))+1)} -> 21.8 | CD11: {=INDEX($AC11:$BU11, 2*(COLUMN(CC11)-COLUMN($BV11))+1)} -> 22.1 | ... CS11: {=INDEX($AC11:$BU11, 2*(COLUMN(CR11)-COLUMN($BV11))+1)} -> 16.7
A12: 203620 | B12: 正常 | D12: 45070 | E12: 45070.292 | F12: 10.06 | G12: 8.6 | H12: 9.3133333 | I12: 11.02 | J12: 13.42 | K12: 15.633333 | L12: 17.4 | M12: 18.62 | N12: 18.82 | O12: 17.893333 | P12: 16.733333 | Q12: 15.873333 | R12: 15.406667 | S12: 15.3 | T12: 19.1 | U12: 98 | V12: 0.10714286 | W12: -0.046341463 | X12: 2731.25 | Y12: 0 | Z12: 2731.25 | AA12: -2731.25 | AB12: 45070.276 | AC12: 8.5 | AD12: 45070.287 | AE12: 8.7 | AF12: 45070.297 | AG12: 8.8 | AH12: 45070.308 | AI12: 9.9 | AJ12: 45070.318 | AK12: 12.3 | AL12: 45070.328 | AM12: 14.7 | AN12: 45070.339 | AO12: 16.7 | AP12: 45070.349 | AQ12: 18.2 | AR12: 45070.36 | AS12: 19.1 | AT12: 45070.37 | AU12: 18.5 | AV12: 45070.381 | AW12: 17.2 | AX12: 45070.391 | AY12: 16.2 | AZ12: 45070.401 | BA12: 15.5 | BB12: 45070.412 | BC12: 15.3 | BD12: 45070.422 | BE12: 15.7 | BF12: 45070.433 | BG12: 15.8 | BH12: 45070.443 | BI12: 15.4 | BJ12: 45070.453 | BK12: 14.6 | BL12: 45070.464 | BM12: 13.8 | BN12: 45070.474 | BO12: 12.8 | BP12: 45070.485 | BQ12: 12 | BR12: 45070.495 | BS12: 10.9 | BT12: 45070.506 | BU12: 9.7 | BW12: {=INDEX($AC12:$BU12, 2*(COLUMN(BV12)-COLUMN($BV12))+1)} -> 8.5 | BX12: {=INDEX($AC12:$BU12, 2*(COLUMN(BW12)-COLUMN($BV12))+1)} -> 8.7 | BY12: {=INDEX($AC12:$BU12, 2*(COLUMN(BX12)-COLUMN($BV12))+1)} -> 8.8 | BZ12: {=INDEX($AC12:$BU12, 2*(COLUMN(BY12)-COLUMN($BV12))+1)} -> 9.9 | CA12: {=INDEX($AC12:$BU12, 2*(COLUMN(BZ12)-COLUMN($BV12))+1)} -> 12.3 | CB12: {=INDEX($AC12:$BU12, 2*(COLUMN(CA12)-COLUMN($BV12))+1)} -> 14.7 | CC12: {=INDEX($AC12:$BU12, 2*(COLUMN(CB12)-COLUMN($BV12))+1)} -> 16.7 | CD12: {=INDEX($AC12:$BU12, 2*(COLUMN(CC12)-COLUMN($BV12))+1)} -> 18.2 | ... CS12: {=INDEX($AC12:$BU12, 2*(COLUMN(CR12)-COLUMN($BV12))+1)} -> 9.7
A13: 207954 | B13: 正常 | D13: 45182 | E13: 45182.292 | F13: 14.24 | G13: 13.6 | H13: 13.1 | I13: 12.7 | J13: 11.8 | K13: 11.2 | L13: 11.8 | M13: 12.9 | N13: 13.4 | O13: 13.3 | P13: 13 | Q13: 12.4 | R13: 11.7 | S13: 11.9 | T13: 13.5 | U13: 0 | W13: -0.0088888889 | X13: 2250.75 | Y13: 0 | Z13: 2250.75 | AA13: -2250.75 | AB13: 45182.271 | AC13: 13.7 | AD13: 45182.281 | AE13: 13.6 | AF13: 45182.292 | AG13: 13.5 | AH13: 45182.302 | AI13: 13.1 | AJ13: 45182.312 | AK13: 12.7 | AL13: 45182.323 | AM13: 11.8 | AN13: 45182.333 | AO13: 11.2 | AP13: 45182.344 | AQ13: 11.8 | AR13: 45182.354 | AS13: 12.9 | AT13: 45182.365 | AU13: 13.4 | AV13: 45182.375 | AW13: 13.3 | AX13: 45182.385 | AY13: 13 | AZ13: 45182.396 | BA13: 12.4 | BB13: 45182.406 | BC13: 11.7 | BD13: 45182.417 | BE13: 11.9 | BF13: 45182.427 | BG13: 12.4 | BH13: 45182.438 | BI13: 12.6 | BJ13: 45182.448 | BK13: 12.9 | BL13: 45182.458 | BM13: 13.7 | BN13: 45182.469 | BO13: 14.3 | BP13: 45182.479 | BQ13: 14.1 | BR13: 45182.49 | BS13: 13.1 | BT13: 45182.5 | BU13: 11.9 | BW13: {=INDEX($AC13:$BU13, 2*(COLUMN(BV13)-COLUMN($BV13))+1)} -> 13.7 | BX13: {=INDEX($AC13:$BU13, 2*(COLUMN(BW13)-COLUMN($BV13))+1)} -> 13.6 | BY13: {=INDEX($AC13:$BU13, 2*(COLUMN(BX13)-COLUMN($BV13))+1)} -> 13.5 | BZ13: {=INDEX($AC13:$BU13, 2*(COLUMN(BY13)-COLUMN($BV13))+1)} -> 13.1 | CA13: {=INDEX($AC13:$BU13, 2*(COLUMN(BZ13)-COLUMN($BV13))+1)} -> 12.7 | CB13: {=INDEX($AC13:$BU13, 2*(COLUMN(CA13)-COLUMN($BV13))+1)} -> 11.8 | CC13: {=INDEX($AC13:$BU13, 2*(COLUMN(CB13)-COLUMN($BV13))+1)} -> 11.2 | CD13: {=INDEX($AC13:$BU13, 2*(COLUMN(CC13)-COLUMN($BV13))+1)} -> 11.8 | ... CS13: {=INDEX($AC13:$BU13, 2*(COLUMN(CR13)-COLUMN($BV13))+1)} -> 11.9
A14: 209646 | B14: 正常 | D14: 45189 | E14: 45189.292 | F14: 16.35 | G14: 15.5 | H14: 14.013333 | I14: 13.506667 | J14: 12.96 | K14: 12.506667 | L14: 12.4 | M14: 12.253333 | N14: 11.173333 | O14: 9.9933333 | P14: 9.6266667 | Q14: 9.6 | R14: 9.16 | S14: 9 | T14: 14.6 | U14: 4 | V14: -0.225 | W14: -0.031818182 | X14: 2091.65 | Y14: 0 | Z14: 2091.65 | AA14: -2091.65 | AB14: 45189.274 | AC14: 15.3 | AD14: 45189.284 | AE14: 15.7 | AF14: 45189.294 | AG14: 14.6 | AH14: 45189.305 | AI14: 13.8 | AJ14: 45189.315 | AK14: 13.4 | AL14: 45189.326 | AM14: 12.8 | AN14: 45189.336 | AO14: 12.4 | AP14: 45189.347 | AQ14: 12.4 | AR14: 45189.357 | AS14: 12.2 | AT14: 45189.367 | AU14: 10.8 | AV14: 45189.378 | AW14: 9.7 | AX14: 45189.388 | AY14: 9.6 | AZ14: 45189.399 | BA14: 9.6 | BB14: 45189.409 | BC14: 9 | BD14: 45189.419 | BE14: 8.7 | BF14: 45189.43 | BG14: 8.4 | BH14: 45189.44 | BI14: 8.1 | BJ14: 45189.451 | BK14: 7.8 | BL14: 45189.461 | BM14: 7.6 | BN14: 45189.472 | BO14: 7.5 | BP14: 45189.482 | BQ14: 7.4 | BR14: 45189.492 | BS14: 7.2 | BT14: 45189.503 | BU14: 6.7 | BW14: {=INDEX($AC14:$BU14, 2*(COLUMN(BV14)-COLUMN($BV14))+1)} -> 15.3 | BX14: {=INDEX($AC14:$BU14, 2*(COLUMN(BW14)-COLUMN($BV14))+1)} -> 15.7 | BY14: {=INDEX($AC14:$BU14, 2*(COLUMN(BX14)-COLUMN($BV14))+1)} -> 14.6 | BZ14: {=INDEX($AC14:$BU14, 2*(COLUMN(BY14)-COLUMN($BV14))+1)} -> 13.8 | CA14: {=INDEX($AC14:$BU14, 2*(COLUMN(BZ14)-COLUMN($BV14))+1)} -> 13.4 | CB14: {=INDEX($AC14:$BU14, 2*(COLUMN(CA14)-COLUMN($BV14))+1)} -> 12.8 | CC14: {=INDEX($AC14:$BU14, 2*(COLUMN(CB14)-COLUMN($BV14))+1)} -> 12.4 | CD14: {=INDEX($AC14:$BU14, 2*(COLUMN(CC14)-COLUMN($BV14))+1)} -> 12.4 | ... CS14: {=INDEX($AC14:$BU14, 2*(COLUMN(CR14)-COLUMN($BV14))+1)} -> 6.7
A15: 212432 | B15: 正常 | D15: 45344 | E15: 45344.292 | F15: 16.27 | G15: 15.5 | H15: 16.946667 | I15: 18.64 | J15: 20.393333 | K15: 21.626667 | L15: 22.093333 | M15: 22.386667 | N15: 22.46 | O15: 22.02 | P15: 21.42 | Q15: 21.146667 | R15: 21.34 | S15: 21.5 | T15: 22.6 | U15: 98 | V15: 0.07244898 | W15: -0.013414634 | X15: 3734.6 | Y15: 0 | Z15: 3734.6 | AA15: -3734.6 | AB15: 45344.276 | AC15: 15.4 | AD15: 45344.287 | AE15: 15.6 | AF15: 45344.297 | AG15: 16.2 | AH15: 45344.308 | AI15: 17.8 | AJ15: 45344.318 | AK15: 19.6 | AL15: 45344.328 | AM15: 21.3 | AN15: 45344.339 | AO15: 22 | AP15: 45344.349 | AQ15: 22.2 | AR15: 45344.36 | AS15: 22.6 | AT15: 45344.37 | AU15: 22.3 | AV15: 45344.381 | AW15: 21.7 | AX15: 45344.391 | AY15: 21.1 | AZ15: 45344.401 | BA15: 21.2 | BB15: 45344.412 | BC15: 21.5 | BD15: 45344.422 | BE15: 21.9 | BF15: 45344.433 | BG15: 22.9 | BH15: 45344.443 | BI15: 24.5 | BJ15: 45344.453 | BK15: 26 | BL15: 45344.464 | BM15: 26.9 | BN15: 45344.474 | BO15: 26.9 | BP15: 45344.485 | BQ15: 26.6 | BR15: 45344.495 | BS15: 26.1 | BT15: 45344.506 | BU15: 25.2 | BW15: {=INDEX($AC15:$BU15, 2*(COLUMN(BV15)-COLUMN($BV15))+1)} -> 15.4 | BX15: {=INDEX($AC15:$BU15, 2*(COLUMN(BW15)-COLUMN($BV15))+1)} -> 15.6 | BY15: {=INDEX($AC15:$BU15, 2*(COLUMN(BX15)-COLUMN($BV15))+1)} -> 16.2 | BZ15: {=INDEX($AC15:$BU15, 2*(COLUMN(BY15)-COLUMN($BV15))+1)} -> 17.8 | CA15: {=INDEX($AC15:$BU15, 2*(COLUMN(BZ15)-COLUMN($BV15))+1)} -> 19.6 | CB15: {=INDEX($AC15:$BU15, 2*(COLUMN(CA15)-COLUMN($BV15))+1)} -> 21.3 | CC15: {=INDEX($AC15:$BU15, 2*(COLUMN(CB15)-COLUMN($BV15))+1)} -> 22 | CD15: {=INDEX($AC15:$BU15, 2*(COLUMN(CC15)-COLUMN($BV15))+1)} -> 22.2 | ... CS15: {=INDEX($AC15:$BU15, 2*(COLUMN(CR15)-COLUMN($BV15))+1)} -> 25.2
A16: 214223 | B16: 正常 | D16: 45117 | E16: 45117.292 | F16: 13.53 | G16: 12.75 | H16: 12.8 | I16: 12.88 | J16: 13.18 | K16: 13.453333 | L16: 13.573333 | M16: 13.366667 | N16: 12.786667 | O16: 12.066667 | P16: 11.726667 | Q16: 11.906667 | R16: 12.386667 | S16: 12.9 | T16: 13.6 | U16: 71 | V16: 0.011971831 | W16: -0.0064220183 | X16: 2294.275 | Y16: 0 | Z16: 2294.275 | AA16: -2294.275 | AB16: 45117.278 | AC16: 12.7 | AD16: 45117.289 | AE16: 12.8 | AF16: 45117.299 | AG16: 12.8 | AH16: 45117.31 | AI16: 12.8 | AJ16: 45117.32 | AK16: 13.1 | AL16: 45117.331 | AM16: 13.4 | AN16: 45117.341 | AO16: 13.6 | AP16: 45117.351 | AQ16: 13.5 | AR16: 45117.362 | AS16: 13 | AT16: 45117.372 | AU16: 12.2 | AV16: 45117.383 | AW16: 11.7 | AX16: 45117.393 | AY16: 11.8 | AZ16: 45117.403 | BA16: 12.2 | BB16: 45117.414 | BC16: 12.9 | BD16: 45117.424 | BE16: 13.4 | BF16: 45117.435 | BG16: 13.4 | BH16: 45117.445 | BI16: 13.3 | BJ16: 45117.456 | BK16: 13.1 | BL16: 45117.466 | BM16: 13.5 | BN16: 45117.476 | BO16: 14.9 | BP16: 45117.487 | BQ16: 15.6 | BR16: 45117.497 | BS16: 15.2 | BT16: 45117.508 | BU16: 15.1 | BW16: {=INDEX($AC16:$BU16, 2*(COLUMN(BV16)-COLUMN($BV16))+1)} -> 12.7 | BX16: {=INDEX($AC16:$BU16, 2*(COLUMN(BW16)-COLUMN($BV16))+1)} -> 12.8 | BY16: {=INDEX($AC16:$BU16, 2*(COLUMN(BX16)-COLUMN($BV16))+1)} -> 12.8 | BZ16: {=INDEX($AC16:$BU16, 2*(COLUMN(BY16)-COLUMN($BV16))+1)} -> 12.8 | CA16: {=INDEX($AC16:$BU16, 2*(COLUMN(BZ16)-COLUMN($BV16))+1)} -> 13.1 | CB16: {=INDEX($AC16:$BU16, 2*(COLUMN(CA16)-COLUMN($BV16))+1)} -> 13.4 | CC16: {=INDEX($AC16:$BU16, 2*(COLUMN(CB16)-COLUMN($BV16))+1)} -> 13.6 | CD16: {=INDEX($AC16:$BU16, 2*(COLUMN(CC16)-COLUMN($BV16))+1)} -> 13.5 | ... CS16: {=INDEX($AC16:$BU16, 2*(COLUMN(CR16)-COLUMN($BV16))+1)} -> 15.1
A17: 203640 | B17: 正常 | D17: 44994 | E17: 44994.292 | F17: 14.49 | G17: 11.8 | H17: 12.84 | I17: 14.12 | J17: 15.74 | K17: 17.3 | L17: 18.16 | M17: 18.5 | N17: 19 | O17: 19.54 | P17: 20.04 | Q17: 19.62 | R17: 18.76 | S17: 18.2 | T17: 20.1 | U17: 132 | V17: 0.062878788 | W17: -0.039583333 | X17: 3129.3 | Y17: 0 | Z17: 3129.3 | AA17: -3129.3 | AB17: 44994.279 | AC17: 11.8 | AD17: 44994.29 | AE17: 11.8 | AF17: 44994.3 | AG17: 12.6 | AH17: 44994.31 | AI17: 13.8 | AJ17: 44994.321 | AK17: 15.4 | AL17: 44994.331 | AM17: 17.1 | AN17: 44994.342 | AO17: 18.1 | AP17: 44994.352 | AQ17: 18.4 | AR17: 44994.363 | AS17: 18.9 | AT17: 44994.373 | AU17: 19.4 | AV17: 44994.383 | AW17: 20.1 | AX17: 44994.394 | AY17: 19.8 | AZ17: 44994.404 | BA17: 18.9 | BB17: 44994.415 | BC17: 18.2 | BD17: 44994.425 | BE17: 17.4 | BF17: 44994.435 | BG17: 17.1 | BH17: 44994.446 | BI17: 16.8 | BJ17: 44994.456 | BK17: 16.6 | BL17: 44994.467 | BM17: 15.9 | BN17: 44994.477 | BO17: 15.1 | BP17: 44994.488 | BQ17: 14.7 | BR17: 44994.498 | BS17: 14.7 | BT17: 44994.508 | BU17: 14.4 | BW17: {=INDEX($AC17:$BU17, 2*(COLUMN(BV17)-COLUMN($BV17))+1)} -> 11.8 | BX17: {=INDEX($AC17:$BU17, 2*(COLUMN(BW17)-COLUMN($BV17))+1)} -> 11.8 | BY17: {=INDEX($AC17:$BU17, 2*(COLUMN(BX17)-COLUMN($BV17))+1)} -> 12.6 | BZ17: {=INDEX($AC17:$BU17, 2*(COLUMN(BY17)-COLUMN($BV17))+1)} -> 13.8 | CA17: {=INDEX($AC17:$BU17, 2*(COLUMN(BZ17)-COLUMN($BV17))+1)} -> 15.4 | CB17: {=INDEX($AC17:$BU17, 2*(COLUMN(CA17)-COLUMN($BV17))+1)} -> 17.1 | CC17: {=INDEX($AC17:$BU17, 2*(COLUMN(CB17)-COLUMN($BV17))+1)} -> 18.1 | CD17: {=INDEX($AC17:$BU17, 2*(COLUMN(CC17)-COLUMN($BV17))+1)} -> 18.4 | ... CS17: {=INDEX($AC17:$BU17, 2*(COLUMN(CR17)-COLUMN($BV17))+1)} -> 14.4
A18: 211268 | B18: 正常 | D18: 44112 | E18: 44112.292 | F18: 13.394409 | G18: 11.975 | H18: 13.87 | I18: 14.02 | J18: 13.35 | K18: 12.76 | L18: 13.446667 | M18: 14.09 | N18: 13.663333 | O18: 13.48 | P18: 13.816667 | Q18: 13.613333 | R18: 12.686667 | S18: 11.94 | T18: 14.22 | U18: 85 | V18: 0.026411765 | W18: -0.024 | X18: 2411.3125 | Y18: 0 | Z18: 2411.3125 | AA18: -2411.3125 | AB18: 44112.278 | AC18: 11.56 | AD18: 44112.288 | AE18: 12.39 | AF18: 44112.299 | AG18: 13.72 | AH18: 44112.309 | AI18: 14.17 | AJ18: 44112.319 | AK18: 13.72 | AL18: 44112.33 | AM18: 12.61 | AN18: 44112.34 | AO18: 13.06 | AP18: 44112.351 | AQ18: 14.22 | AR18: 44112.361 | AS18: 13.83 | AT18: 44112.372 | AU18: 13.33 | AV18: 44112.382 | AW18: 13.78 | AX18: 44112.392 | AY18: 13.89 | AZ18: 44112.403 | BA18: 13.06 | BB18: 44112.413 | BC18: 11.94 | BD18: 44112.424 | BE18: 11.39 | BF18: 44112.434 | BG18: 11.61 | BH18: 44112.444 | BI18: 12.11 | BJ18: 44112.455 | BK18: 11.83 | BL18: 44112.465 | BM18: 11.22 | BN18: 44112.476 | BO18: 11.33 | BP18: 44112.486 | BQ18: 12.61 | BR18: 44112.497 | BS18: 13.61 | BT18: 44112.507 | BU18: 13.5 | BW18: {=INDEX($AC18:$BU18, 2*(COLUMN(BV18)-COLUMN($BV18))+1)} -> 11.56 | BX18: {=INDEX($AC18:$BU18, 2*(COLUMN(BW18)-COLUMN($BV18))+1)} -> 12.39 | BY18: {=INDEX($AC18:$BU18, 2*(COLUMN(BX18)-COLUMN($BV18))+1)} -> 13.72 | BZ18: {=INDEX($AC18:$BU18, 2*(COLUMN(BY18)-COLUMN($BV18))+1)} -> 14.17 | CA18: {=INDEX($AC18:$BU18, 2*(COLUMN(BZ18)-COLUMN($BV18))+1)} -> 13.72 | CB18: {=INDEX($AC18:$BU18, 2*(COLUMN(CA18)-COLUMN($BV18))+1)} -> 12.61 | CC18: {=INDEX($AC18:$BU18, 2*(COLUMN(CB18)-COLUMN($BV18))+1)} -> 13.06 | CD18: {=INDEX($AC18:$BU18, 2*(COLUMN(CC18)-COLUMN($BV18))+1)} -> 14.22 | ... CS18: {=INDEX($AC18:$BU18, 2*(COLUMN(CR18)-COLUMN($BV18))+1)} -> 13.5
A19: 218877 | B19: 正常 | D19: 45192 | E19: 45192.292 | F19: 9.6624567 | G19: 9.55 | H19: 9.0866667 | I19: 8.9866667 | J19: 8.8466667 | K19: 8.4733333 | L19: 8.22 | M19: 7.66 | N19: 7.5733333 | O19: 8.9266667 | P19: 10.573333 | Q19: 11.873333 | R19: 13.226667 | S19: 14.7 | T19: 14.7 | U19: 178 | V19: 0.028932584 | W19: 0 | X19: 1733.575 | Y19: 0 | Z19: 1733.575 | AA19: -1733.575 | AB19: 45192.28 | AC19: 9.7 | AD19: 45192.29 | AE19: 9.4 | AF19: 45192.301 | AG19: 9.1 | AH19: 45192.311 | AI19: 9 | AJ19: 45192.322 | AK19: 8.9 | AL19: 45192.332 | AM19: 8.5 | AN19: 45192.342 | AO19: 8.3 | AP19: 45192.353 | AQ19: 7.7 | AR19: 45192.363 | AS19: 7.4 | AT19: 45192.374 | AU19: 8.7 | AV19: 45192.384 | AW19: 10.4 | AX19: 45192.394 | AY19: 11.7 | AZ19: 45192.405 | BA19: 13 | BB19: 45192.415 | BC19: 14.7 | BD19: 45192.426 | BE19: 15.9 | BF19: 45192.436 | BG19: 16.3 | BH19: 45192.447 | BI19: 16.6 | BJ19: 45192.457 | BK19: 17.2 | BL19: 45192.467 | BM19: 17 | BN19: 45192.478 | BO19: 16.8 | BP19: 45192.488 | BQ19: 16.9 | BR19: 45192.499 | BS19: 16.7 | BT19: 45192.509 | BU19: 16.6 | BW19: {=INDEX($AC19:$BU19, 2*(COLUMN(BV19)-COLUMN($BV19))+1)} -> 9.7 | BX19: {=INDEX($AC19:$BU19, 2*(COLUMN(BW19)-COLUMN($BV19))+1)} -> 9.4 | BY19: {=INDEX($AC19:$BU19, 2*(COLUMN(BX19)-COLUMN($BV19))+1)} -> 9.1 | BZ19: {=INDEX($AC19:$BU19, 2*(COLUMN(BY19)-COLUMN($BV19))+1)} -> 9 | CA19: {=INDEX($AC19:$BU19, 2*(COLUMN(BZ19)-COLUMN($BV19))+1)} -> 8.9 | CB19: {=INDEX($AC19:$BU19, 2*(COLUMN(CA19)-COLUMN($BV19))+1)} -> 8.5 | CC19: {=INDEX($AC19:$BU19, 2*(COLUMN(CB19)-COLUMN($BV19))+1)} -> 8.3 | CD19: {=INDEX($AC19:$BU19, 2*(COLUMN(CC19)-COLUMN($BV19))+1)} -> 7.7 | ... CS19: {=INDEX($AC19:$BU19, 2*(COLUMN(CR19)-COLUMN($BV19))+1)} -> 16.6
A20: 219341 | B20: 正常 | D20: 45084 | E20: 45084.292 | F20: 10.97 | G20: 12.45 | H20: 11.4 | I20: 11.34 | J20: 11.36 | K20: 12.18 | L20: 13.42 | M20: 13.78 | N20: 12.92 | O20: 11.5 | P20: 9.88 | Q20: 8.6 | R20: 8.62 | S20: 8.9 | T20: 13.9 | U20: 81 | V20: 0.017901235 | W20: -0.050505051 | X20: 2035.125 | Y20: 0 | Z20: 2035.125 | AA20: -2035.125 | AB20: 45084.275 | AC20: 12.7 | AD20: 45084.285 | AE20: 12.2 | AF20: 45084.296 | AG20: 11.4 | AH20: 45084.306 | AI20: 11.4 | AJ20: 45084.317 | AK20: 11.3 | AL20: 45084.327 | AM20: 11.4 | AN20: 45084.338 | AO20: 12.7 | AP20: 45084.348 | AQ20: 13.9 | AR20: 45084.358 | AS20: 13.7 | AT20: 45084.369 | AU20: 12.4 | AV20: 45084.379 | AW20: 10.9 | AX20: 45084.39 | AY20: 9.2 | AZ20: 45084.4 | BA20: 8.2 | BB20: 45084.41 | BC20: 8.9 | BD20: 45084.421 | BE20: 10.1 | BF20: 45084.431 | BG20: 10.7 | BH20: 45084.442 | BI20: 10.8 | BJ20: 45084.452 | BK20: 10.3 | BL20: 45084.463 | BM20: 9.3 | BN20: 45084.473 | BO20: 8.6 | BP20: 45084.483 | BQ20: 8.8 | BR20: 45084.494 | BS20: 9.8 | BT20: 45084.504 | BU20: 10.6 | BW20: {=INDEX($AC20:$BU20, 2*(COLUMN(BV20)-COLUMN($BV20))+1)} -> 12.7 | BX20: {=INDEX($AC20:$BU20, 2*(COLUMN(BW20)-COLUMN($BV20))+1)} -> 12.2 | BY20: {=INDEX($AC20:$BU20, 2*(COLUMN(BX20)-COLUMN($BV20))+1)} -> 11.4 | BZ20: {=INDEX($AC20:$BU20, 2*(COLUMN(BY20)-COLUMN($BV20))+1)} -> 11.4 | CA20: {=INDEX($AC20:$BU20, 2*(COLUMN(BZ20)-COLUMN($BV20))+1)} -> 11.3 | CB20: {=INDEX($AC20:$BU20, 2*(COLUMN(CA20)-COLUMN($BV20))+1)} -> 11.4 | CC20: {=INDEX($AC20:$BU20, 2*(COLUMN(CB20)-COLUMN($BV20))+1)} -> 12.7 | CD20: {=INDEX($AC20:$BU20, 2*(COLUMN(CC20)-COLUMN($BV20))+1)} -> 13.9 | ... CS20: {=INDEX($AC20:$BU20, 2*(COLUMN(CR20)-COLUMN($BV20))+1)} -> 10.6
A21: 225682 | B21: 正常 | D21: 45219 | E21: 45219.292 | F21: 11 | G21: 9.1 | H21: 6.3333333 | I21: 5.5666667 | J21: 5.2 | K21: 4.9 | L21: 4.8666667 | M21: 5.3 | N21: 6.1 | O21: 7 | P21: 7.9 | Q21: 8.8666667 | R21: 9.5333333 | S21: 9.7 | T21: 9.7 | U21: 170 | V21: 0.0035294118 | W21: 0 | X21: 1214.5 | Y21: 0 | Z21: 1214.5 | AA21: -1214.5 | AB21: 45219.274 | AC21: 9.6 | AD21: 45219.285 | AE21: 8.6 | AF21: 45219.295 | AG21: 7.2 | AH21: 45219.306 | AI21: 5.9 | AJ21: 45219.316 | AK21: 5.4 | AL21: 45219.326 | AM21: 5.1 | AN21: 45219.337 | AO21: 4.8 | AP21: 45219.347 | AQ21: 4.9 | AR21: 45219.358 | AS21: 5.5 | AT21: 45219.368 | AU21: 6.4 | AV21: 45219.378 | AW21: 7.3 | AX21: 45219.389 | AY21: 8.2 | AZ21: 45219.399 | BA21: 9.2 | BB21: 45219.41 | BC21: 9.7 | BD21: 45219.42 | BE21: 9.4 | BF21: 45219.431 | BG21: 9.7 | BH21: 45219.441 | BI21: 10.4 | BJ21: 45219.451 | BK21: 10.3 | BL21: 45219.462 | BM21: 10.1 | BN21: 45219.472 | BO21: 10.2 | BP21: 45219.483 | BQ21: 9.8 | BR21: 45219.493 | BS21: 9.6 | BT21: 45219.503 | BU21: 9.3 | BW21: {=INDEX($AC21:$BU21, 2*(COLUMN(BV21)-COLUMN($BV21))+1)} -> 9.6 | BX21: {=INDEX($AC21:$BU21, 2*(COLUMN(BW21)-COLUMN($BV21))+1)} -> 8.6 | BY21: {=INDEX($AC21:$BU21, 2*(COLUMN(BX21)-COLUMN($BV21))+1)} -> 7.2 | BZ21: {=INDEX($AC21:$BU21, 2*(COLUMN(BY21)-COLUMN($BV21))+1)} -> 5.9 | CA21: {=INDEX($AC21:$BU21, 2*(COLUMN(BZ21)-COLUMN($BV21))+1)} -> 5.4 | CB21: {=INDEX($AC21:$BU21, 2*(COLUMN(CA21)-COLUMN($BV21))+1)} -> 5.1 | CC21: {=INDEX($AC21:$BU21, 2*(COLUMN(CB21)-COLUMN($BV21))+1)} -> 4.8 | CD21: {=INDEX($AC21:$BU21, 2*(COLUMN(CC21)-COLUMN($BV21))+1)} -> 4.9 | ... CS21: {=INDEX($AC21:$BU21, 2*(COLUMN(CR21)-COLUMN($BV21))+1)} -> 9.3
A22: 227647 | B22: 正常 | D22: 45207 | E22: 45207.292 | F22: 11.649288 | G22: 12.8 | H22: 13.06 | I22: 13.68 | J22: 13.44 | K22: 12.7 | L22: 12.18 | M22: 11.62 | N22: 11.36 | O22: 11.6 | P22: 11.42 | Q22: 10.64 | R22: 10.4 | S22: 10.4 | T22: 13.7 | U22: 27 | V22: 0.033333333 | W22: -0.021568627 | X22: 2155.5 | Y22: 0 | Z22: 2155.5 | AA22: -2155.5 | AB22: 45207.279 | AC22: 12.8 | AD22: 45207.29 | AE22: 12.8 | AF22: 45207.3 | AG22: 12.9 | AH22: 45207.31 | AI22: 13.7 | AJ22: 45207.321 | AK22: 13.6 | AL22: 45207.331 | AM22: 12.8 | AN22: 45207.342 | AO22: 12.3 | AP22: 45207.352 | AQ22: 11.7 | AR22: 45207.363 | AS22: 11.3 | AT22: 45207.373 | AU22: 11.6 | AV22: 45207.383 | AW22: 11.6 | AX22: 45207.394 | AY22: 10.7 | AZ22: 45207.404 | BA22: 10.4 | BB22: 45207.415 | BC22: 10.4 | BD22: 45207.425 | BE22: 10.3 | BF22: 45207.435 | BG22: 10.4 | BH22: 45207.446 | BI22: 10.1 | BJ22: 45207.456 | BK22: 9.2 | BL22: 45207.467 | BM22: 8.1 | BN22: 45207.477 | BO22: 7.1 | BP22: 45207.488 | BQ22: 6.5 | BR22: 45207.498 | BS22: 6.1 | BT22: 45207.508 | BU22: 5.8 | BW22: {=INDEX($AC22:$BU22, 2*(COLUMN(BV22)-COLUMN($BV22))+1)} -> 12.8 | BX22: {=INDEX($AC22:$BU22, 2*(COLUMN(BW22)-COLUMN($BV22))+1)} -> 12.8 | BY22: {=INDEX($AC22:$BU22, 2*(COLUMN(BX22)-COLUMN($BV22))+1)} -> 12.9 | BZ22: {=INDEX($AC22:$BU22, 2*(COLUMN(BY22)-COLUMN($BV22))+1)} -> 13.7 | CA22: {=INDEX($AC22:$BU22, 2*(COLUMN(BZ22)-COLUMN($BV22))+1)} -> 13.6 | CB22: {=INDEX($AC22:$BU22, 2*(COLUMN(CA22)-COLUMN($BV22))+1)} -> 12.8 | CC22: {=INDEX($AC22:$BU22, 2*(COLUMN(CB22)-COLUMN($BV22))+1)} -> 12.3 | CD22: {=INDEX($AC22:$BU22, 2*(COLUMN(CC22)-COLUMN($BV22))+1)} -> 11.7 | ... CS22: {=INDEX($AC22:$BU22, 2*(COLUMN(CR22)-COLUMN($BV22))+1)} -> 5.8
A23: 232971 | B23: 正常 | D23: 45112 | E23: 45112.292 | F23: 15.93 | G23: 17.866667 | H23: 16.8 | I23: 16.3 | J23: 15.4 | K23: 15.3 | L23: 15.1 | M23: 13.8 | N23: 12.7 | O23: 11.7 | P23: 11.2 | Q23: 10.9 | R23: 10.2 | S23: 10 | T23: 17.2 | U23: 0 | W23: -0.04 | X23: 2450 | Y23: 0 | Z23: 2450 | AA23: -2450 | AB23: 45112.271 | AC23: 18.6 | AD23: 45112.281 | AE23: 17.8 | AF23: 45112.292 | AG23: 17.2 | AH23: 45112.302 | AI23: 16.8 | AJ23: 45112.312 | AK23: 16.3 | AL23: 45112.323 | AM23: 15.4 | AN23: 45112.333 | AO23: 15.3 | AP23: 45112.344 | AQ23: 15.1 | AR23: 45112.354 | AS23: 13.8 | AT23: 45112.365 | AU23: 12.7 | AV23: 45112.375 | AW23: 11.7 | AX23: 45112.385 | AY23: 11.2 | AZ23: 45112.396 | BA23: 10.9 | BB23: 45112.406 | BC23: 10.2 | BD23: 45112.417 | BE23: 10 | BF23: 45112.427 | BG23: 11.2 | BH23: 45112.438 | BI23: 12.5 | BJ23: 45112.448 | BK23: 13.1 | BL23: 45112.458 | BM23: 13.3 | BN23: 45112.469 | BO23: 13.4 | BP23: 45112.479 | BQ23: 13.4 | BR23: 45112.49 | BS23: 12.9 | BT23: 45112.5 | BU23: 12.6 | BW23: {=INDEX($AC23:$BU23, 2*(COLUMN(BV23)-COLUMN($BV23))+1)} -> 18.6 | BX23: {=INDEX($AC23:$BU23, 2*(COLUMN(BW23)-COLUMN($BV23))+1)} -> 17.8 | BY23: {=INDEX($AC23:$BU23, 2*(COLUMN(BX23)-COLUMN($BV23))+1)} -> 17.2 | BZ23: {=INDEX($AC23:$BU23, 2*(COLUMN(BY23)-COLUMN($BV23))+1)} -> 16.8 | CA23: {=INDEX($AC23:$BU23, 2*(COLUMN(BZ23)-COLUMN($BV23))+1)} -> 16.3 | CB23: {=INDEX($AC23:$BU23, 2*(COLUMN(CA23)-COLUMN($BV23))+1)} -> 15.4 | CC23: {=INDEX($AC23:$BU23, 2*(COLUMN(CB23)-COLUMN($BV23))+1)} -> 15.3 | CD23: {=INDEX($AC23:$BU23, 2*(COLUMN(CC23)-COLUMN($BV23))+1)} -> 15.1 | ... CS23: {=INDEX($AC23:$BU23, 2*(COLUMN(CR23)-COLUMN($BV23))+1)} -> 12.6
A24: 228821 | B24: 正常 | D24: 44347 | E24: 44347.292 | F24: 12.5 | G24: 14 | H24: 17.14 | I24: 18.846667 | J24: 19.786667 | K24: 19.686667 | L24: 19.573333 | M24: 19.32 | N24: 18.786667 | O24: 18.633333 | P24: 18.066667 | Q24: 17.133333 | R24: 16.58 | S24: 15.8 | T24: 19.8 | U24: 43 | V24: 0.13488372 | W24: -0.02919708 | X24: 3276.8 | Y24: 0 | Z24: 3276.8 | AA24: -3276.8 | AB24: 44347.28 | AC24: 13.2 | AD24: 44347.29 | AE24: 14.8 | AF24: 44347.301 | AG24: 16.9 | AH24: 44347.311 | AI24: 18.7 | AJ24: 44347.322 | AK24: 19.8 | AL24: 44347.332 | AM24: 19.7 | AN24: 44347.342 | AO24: 19.6 | AP24: 44347.353 | AQ24: 19.4 | AR24: 44347.363 | AS24: 18.8 | AT24: 44347.374 | AU24: 18.7 | AV24: 44347.384 | AW24: 18.2 | AX24: 44347.394 | AY24: 17.2 | AZ24: 44347.405 | BA24: 16.7 | BB24: 44347.415 | BC24: 15.8 | BD24: 44347.426 | BE24: 15.7 | BF24: 44347.436 | BG24: 15.2 | BH24: 44347.447 | BI24: 14.4 | BJ24: 44347.457 | BK24: 14.1 | BL24: 44347.467 | BM24: 13.7 | BN24: 44347.478 | BO24: 13.9 | BP24: 44347.488 | BQ24: 15 | BR24: 44347.499 | BS24: 17.4 | BT24: 44347.509 | BU24: 20.1 | BW24: {=INDEX($AC24:$BU24, 2*(COLUMN(BV24)-COLUMN($BV24))+1)} -> 13.2 | BX24: {=INDEX($AC24:$BU24, 2*(COLUMN(BW24)-COLUMN($BV24))+1)} -> 14.8 | BY24: {=INDEX($AC24:$BU24, 2*(COLUMN(BX24)-COLUMN($BV24))+1)} -> 16.9 | BZ24: {=INDEX($AC24:$BU24, 2*(COLUMN(BY24)-COLUMN($BV24))+1)} -> 18.7 | CA24: {=INDEX($AC24:$BU24, 2*(COLUMN(BZ24)-COLUMN($BV24))+1)} -> 19.8 | CB24: {=INDEX($AC24:$BU24, 2*(COLUMN(CA24)-COLUMN($BV24))+1)} -> 19.7 | CC24: {=INDEX($AC24:$BU24, 2*(COLUMN(CB24)-COLUMN($BV24))+1)} -> 19.6 | CD24: {=INDEX($AC24:$BU24, 2*(COLUMN(CC24)-COLUMN($BV24))+1)} -> 19.4 | ... CS24: {=INDEX($AC24:$BU24, 2*(COLUMN(CR24)-COLUMN($BV24))+1)} -> 20.1
A25: 240863 | B25: 正常 | D25: 45376 | E25: 45376.292 | F25: 13.740949 | G25: 12.3 | H25: 12.046667 | I25: 11.873333 | J25: 11.746667 | K25: 11.52 | L25: 9.5133333 | M25: 4.5466667 | N25: 4.3733333 | O25: 4.2733333 | P25: 4.1733333 | Q25: 4.1 | R25: 4.0733333 | S25: 4 | T25: 12.1 | U25: 11 | V25: -0.018181818 | W25: -0.047928994 | X25: 1355.85 | Y25: 0 | Z25: 1355.85 | AA25: -1355.85 | AB25: 45376.278 | AC25: 12.4 | AD25: 45376.289 | AE25: 12.2 | AF25: 45376.299 | AG25: 12.1 | AH25: 45376.31 | AI25: 11.9 | AJ25: 45376.32 | AK25: 11.8 | AL25: 45376.331 | AM25: 11.6 | AN25: 45376.341 | AO25: 11.3 | AP25: 45376.351 | AQ25: 4.6 | AR25: 45376.362 | AS25: 4.4 | AT25: 45376.372 | AU25: 4.3 | AV25: 45376.383 | AW25: 4.2 | AX25: 45376.393 | AY25: 4.1 | AZ25: 45376.403 | BA25: 4.1 | BB25: 45376.414 | BC25: 4 | BD25: 45376.424 | BE25: 3.9 | BF25: 45376.435 | BG25: 3.9 | BH25: 45376.445 | BI25: 3.8 | BJ25: 45376.456 | BK25: 4.8 | BL25: 45376.466 | BM25: 5.9 | BN25: 45376.476 | BO25: 5.7 | BP25: 45376.487 | BQ25: 5.6 | BR25: 45376.497 | BS25: 5.8 | BT25: 45376.508 | BU25: 5.6 | BW25: {=INDEX($AC25:$BU25, 2*(COLUMN(BV25)-COLUMN($BV25))+1)} -> 12.4 | BX25: {=INDEX($AC25:$BU25, 2*(COLUMN(BW25)-COLUMN($BV25))+1)} -> 12.2 | BY25: {=INDEX($AC25:$BU25, 2*(COLUMN(BX25)-COLUMN($BV25))+1)} -> 12.1 | BZ25: {=INDEX($AC25:$BU25, 2*(COLUMN(BY25)-COLUMN($BV25))+1)} -> 11.9 | CA25: {=INDEX($AC25:$BU25, 2*(COLUMN(BZ25)-COLUMN($BV25))+1)} -> 11.8 | CB25: {=INDEX($AC25:$BU25, 2*(COLUMN(CA25)-COLUMN($BV25))+1)} -> 11.6 | CC25: {=INDEX($AC25:$BU25, 2*(COLUMN(CB25)-COLUMN($BV25))+1)} -> 11.3 | CD25: {=INDEX($AC25:$BU25, 2*(COLUMN(CC25)-COLUMN($BV25))+1)} -> 4.6 | ... CS25: {=INDEX($AC25:$BU25, 2*(COLUMN(CR25)-COLUMN($BV25))+1)} -> 5.6
A26: 228411 | B26: 正常 | D26: 45030 | E26: 45030.292 | F26: 12.4 | G26: 11.1 | H26: 12.38 | I26: 14.28 | J26: 16.4 | K26: 18.04 | L26: 19.1 | M26: 20.3 | N26: 21.92 | O26: 23.56 | P26: 24.56 | Q26: 24.04 | R26: 21.98 | S26: 20.6 | T26: 24.8 | U26: 144 | V26: 0.095138889 | W26: -0.11666667 | X26: 3486.15 | Y26: 0 | Z26: 3486.15 | AA26: -3486.15 | AB26: 45030.277 | AC26: 11.3 | AD26: 45030.287 | AE26: 10.9 | AF26: 45030.298 | AG26: 11.7 | AH26: 45030.308 | AI26: 13.4 | AJ26: 45030.319 | AK26: 15.6 | AL26: 45030.329 | AM26: 17.6 | AN26: 45030.34 | AO26: 18.7 | AP26: 45030.35 | AQ26: 19.7 | AR26: 45030.36 | AS26: 21.2 | AT26: 45030.371 | AU26: 23 | AV26: 45030.381 | AW26: 24.4 | AX26: 45030.392 | AY26: 24.8 | AZ26: 45030.402 | BA26: 22.9 | BB26: 45030.412 | BC26: 20.6 | BD26: 45030.423 | BE26: 18.4 | BF26: 45030.433 | BG26: 16.1 | BH26: 45030.444 | BI26: 14.1 | BJ26: 45030.454 | BK26: 12.8 | BL26: 45030.465 | BM26: 11.6 | BN26: 45030.475 | BO26: 9.7 | BP26: 45030.485 | BQ26: 7.8 | BR26: 45030.496 | BS26: 6.5 | BT26: 45030.506 | BU26: 6.7 | BW26: {=INDEX($AC26:$BU26, 2*(COLUMN(BV26)-COLUMN($BV26))+1)} -> 11.3 | BX26: {=INDEX($AC26:$BU26, 2*(COLUMN(BW26)-COLUMN($BV26))+1)} -> 10.9 | BY26: {=INDEX($AC26:$BU26, 2*(COLUMN(BX26)-COLUMN($BV26))+1)} -> 11.7 | BZ26: {=INDEX($AC26:$BU26, 2*(COLUMN(BY26)-COLUMN($BV26))+1)} -> 13.4 | CA26: {=INDEX($AC26:$BU26, 2*(COLUMN(BZ26)-COLUMN($BV26))+1)} -> 15.6 | CB26: {=INDEX($AC26:$BU26, 2*(COLUMN(CA26)-COLUMN($BV26))+1)} -> 17.6 | CC26: {=INDEX($AC26:$BU26, 2*(COLUMN(CB26)-COLUMN($BV26))+1)} -> 18.7 | CD26: {=INDEX($AC26:$BU26, 2*(COLUMN(CC26)-COLUMN($BV26))+1)} -> 19.7 | ... CS26: {=INDEX($AC26:$BU26, 2*(COLUMN(CR26)-COLUMN($BV26))+1)} -> 6.7
A27: 234632 | B27: 正常 | D27: 45206 | E27: 45206.292 | F27: 12.99 | G27: 11.5 | H27: 10.48 | I27: 9.92 | J27: 9.72 | K27: 10.18 | L27: 10.14 | M27: 9.14 | N27: 8.34 | O27: 8.52 | P27: 9.24 | Q27: 9.4 | R27: 8.6 | S27: 8.4 | T27: 10.8 | U27: 3 | V27: -0.23333333 | W27: -0.013559322 | X27: 1704.45 | Y27: 0 | Z27: 1704.45 | AA27: -1704.45 | AB27: 45206.273 | AC27: 11.9 | AD27: 45206.283 | AE27: 11.1 | AF27: 45206.294 | AG27: 10.8 | AH27: 45206.304 | AI27: 10.4 | AJ27: 45206.315 | AK27: 9.8 | AL27: 45206.325 | AM27: 9.7 | AN27: 45206.335 | AO27: 10.3 | AP27: 45206.346 | AQ27: 10.1 | AR27: 45206.356 | AS27: 8.9 | AT27: 45206.367 | AU27: 8.2 | AV27: 45206.377 | AW27: 8.6 | AX27: 45206.387 | AY27: 9.4 | AZ27: 45206.398 | BA27: 9.4 | BB27: 45206.408 | BC27: 8.4 | BD27: 45206.419 | BE27: 7 | BF27: 45206.429 | BG27: 6.1 | BH27: 45206.44 | BI27: 6.1 | BJ27: 45206.45 | BK27: 6.6 | BL27: 45206.46 | BM27: 7.2 | BN27: 45206.471 | BO27: 7.1 | BP27: 45206.481 | BQ27: 6.7 | BR27: 45206.492 | BS27: 6.1 | BT27: 45206.502 | BU27: 5.8 | BW27: {=INDEX($AC27:$BU27, 2*(COLUMN(BV27)-COLUMN($BV27))+1)} -> 11.9 | BX27: {=INDEX($AC27:$BU27, 2*(COLUMN(BW27)-COLUMN($BV27))+1)} -> 11.1 | BY27: {=INDEX($AC27:$BU27, 2*(COLUMN(BX27)-COLUMN($BV27))+1)} -> 10.8 | BZ27: {=INDEX($AC27:$BU27, 2*(COLUMN(BY27)-COLUMN($BV27))+1)} -> 10.4 | CA27: {=INDEX($AC27:$BU27, 2*(COLUMN(BZ27)-COLUMN($BV27))+1)} -> 9.8 | CB27: {=INDEX($AC27:$BU27, 2*(COLUMN(CA27)-COLUMN($BV27))+1)} -> 9.7 | CC27: {=INDEX($AC27:$BU27, 2*(COLUMN(CB27)-COLUMN($BV27))+1)} -> 10.3 | CD27: {=INDEX($AC27:$BU27, 2*(COLUMN(CC27)-COLUMN($BV27))+1)} -> 10.1 | ... CS27: {=INDEX($AC27:$BU27, 2*(COLUMN(CR27)-COLUMN($BV27))+1)} -> 5.8
A28: 244505 | B28: 正常 | D28: 45288 | E28: 45288.292 | F28: 8.4199219 | G28: 6.5 | H28: 5.46 | I28: 4.9 | J28: 4.76 | K28: 5.76 | L28: 7.62 | M28: 9.06 | N28: 9.96 | O28: 10.82 | P28: 11.5 | Q28: 11.84 | R28: 11.62 | S28: 11.2 | T28: 11.9 | U28: 159 | V28: 0.033962264 | W28: -0.033333333 | X28: 1532.25 | Y28: 0 | Z28: 1532.25 | AA28: -1532.25 | AB28: 45288.277 | AC28: 6.7 | AD28: 45288.287 | AE28: 6.3 | AF28: 45288.298 | AG28: 5.7 | AH28: 45288.308 | AI28: 5.1 | AJ28: 45288.319 | AK28: 4.6 | AL28: 45288.329 | AM28: 5 | AN28: 45288.34 | AO28: 6.9 | AP28: 45288.35 | AQ28: 8.7 | AR28: 45288.36 | AS28: 9.6 | AT28: 45288.371 | AU28: 10.5 | AV28: 45288.381 | AW28: 11.3 | AX28: 45288.392 | AY28: 11.8 | AZ28: 45288.402 | BA28: 11.9 | BB28: 45288.412 | BC28: 11.2 | BD28: 45288.423 | BE28: 10.2 | BF28: 45288.433 | BG28: 10.1 | BH28: 45288.444 | BI28: 10.1 | BJ28: 45288.454 | BK28: 9.5 | BL28: 45288.465 | BM28: 8.9 | BN28: 45288.475 | BO28: 8.1 | BP28: 45288.485 | BQ28: 7.3 | BR28: 45288.496 | BS28: 6.7 | BT28: 45288.506 | BU28: 6.2 | BW28: {=INDEX($AC28:$BU28, 2*(COLUMN(BV28)-COLUMN($BV28))+1)} -> 6.7 | BX28: {=INDEX($AC28:$BU28, 2*(COLUMN(BW28)-COLUMN($BV28))+1)} -> 6.3 | BY28: {=INDEX($AC28:$BU28, 2*(COLUMN(BX28)-COLUMN($BV28))+1)} -> 5.7 | BZ28: {=INDEX($AC28:$BU28, 2*(COLUMN(BY28)-COLUMN($BV28))+1)} -> 5.1 | CA28: {=INDEX($AC28:$BU28, 2*(COLUMN(BZ28)-COLUMN($BV28))+1)} -> 4.6 | CB28: {=INDEX($AC28:$BU28, 2*(COLUMN(CA28)-COLUMN($BV28))+1)} -> 5 | CC28: {=INDEX($AC28:$BU28, 2*(COLUMN(CB28)-COLUMN($BV28))+1)} -> 6.9 | CD28: {=INDEX($AC28:$BU28, 2*(COLUMN(CC28)-COLUMN($BV28))+1)} -> 8.7 | ... CS28: {=INDEX($AC28:$BU28, 2*(COLUMN(CR28)-COLUMN($BV28))+1)} -> 6.2
A29: 237948 | B29: 正常 | D29: 44357 | E29: 44357.292 | F29: 8.04 | G29: 5.6 | H29: 9.3266667 | I29: 11.146667 | J29: 12.066667 | K29: 12.086667 | L29: 11.526667 | M29: 11.84 | N29: 13.253333 | O29: 13.52 | P29: 11.66 | Q29: 9.0133333 | R29: 6.9466667 | S29: 6.2 | T29: 14 | U29: 112 | V29: 0.075 | W29: -0.11470588 | X29: 1924.3 | Y29: 0 | Z29: 1924.3 | AA29: -1924.3 | AB29: 44357.276 | AC29: 5.3 | AD29: 44357.286 | AE29: 5.9 | AF29: 44357.297 | AG29: 8.1 | AH29: 44357.307 | AI29: 10.4 | AJ29: 44357.317 | AK29: 11.8 | AL29: 44357.328 | AM29: 12.3 | AN29: 44357.338 | AO29: 11.9 | AP29: 44357.349 | AQ29: 11.2 | AR29: 44357.359 | AS29: 12.4 | AT29: 44357.369 | AU29: 14 | AV29: 44357.38 | AW29: 13.1 | AX29: 44357.39 | AY29: 10.4 | AZ29: 44357.401 | BA29: 7.8 | BB29: 44357.411 | BC29: 6.2 | BD29: 44357.422 | BE29: 5.1 | BF29: 44357.432 | BG29: 4.1 | BH29: 44357.442 | BI29: 3.6 | BJ29: 44357.453 | BK29: 3.9 | BL29: 44357.463 | BM29: 5.2 | BN29: 44357.474 | BO29: 5.8 | BP29: 44357.484 | BQ29: 5.8 | BR29: 44357.494 | BS29: 6.1 | BT29: 44357.505 | BU29: 6.6 | BW29: {=INDEX($AC29:$BU29, 2*(COLUMN(BV29)-COLUMN($BV29))+1)} -> 5.3 | BX29: {=INDEX($AC29:$BU29, 2*(COLUMN(BW29)-COLUMN($BV29))+1)} -> 5.9 | BY29: {=INDEX($AC29:$BU29, 2*(COLUMN(BX29)-COLUMN($BV29))+1)} -> 8.1 | BZ29: {=INDEX($AC29:$BU29, 2*(COLUMN(BY29)-COLUMN($BV29))+1)} -> 10.4 | CA29: {=INDEX($AC29:$BU29, 2*(COLUMN(BZ29)-COLUMN($BV29))+1)} -> 11.8 | CB29: {=INDEX($AC29:$BU29, 2*(COLUMN(CA29)-COLUMN($BV29))+1)} -> 12.3 | CC29: {=INDEX($AC29:$BU29, 2*(COLUMN(CB29)-COLUMN($BV29))+1)} -> 11.9 | CD29: {=INDEX($AC29:$BU29, 2*(COLUMN(CC29)-COLUMN($BV29))+1)} -> 11.2 | ... CS29: {=INDEX($AC29:$BU29, 2*(COLUMN(CR29)-COLUMN($BV29))+1)} -> 6.6
A30: 238967 | B30: 正常 | D30: 44546 | E30: 44546.292 | F30: 16.44 | G30: 15.4 | H30: 19.26 | I30: 21.5 | J30: 23.34 | K30: 24.44 | L30: 25.06 | M30: 25.22 | N30: 24.7 | O30: 23.56 | P30: 21.84 | Q30: 20.14 | R30: 18.86 | S30: 17.9 | T30: 25.3 | U30: 87 | V30: 0.1137931 | W30: -0.079569892 | X30: 3968.55 | Y30: 0 | Z30: 3968.55 | AA30: -3968.55 | AB30: 44546.279 | AC30: 14.4 | AD30: 44546.29 | AE30: 16.4 | AF30: 44546.3 | AG30: 18.8 | AH30: 44546.31 | AI30: 21.1 | AJ30: 44546.321 | AK30: 23.1 | AL30: 44546.331 | AM30: 24.3 | AN30: 44546.342 | AO30: 25 | AP30: 44546.352 | AQ30: 25.3 | AR30: 44546.363 | AS30: 24.9 | AT30: 44546.373 | AU30: 23.9 | AV30: 44546.383 | AW30: 22.2 | AX30: 44546.394 | AY30: 20.4 | AZ30: 44546.404 | BA30: 19.1 | BB30: 44546.415 | BC30: 17.9 | BD30: 44546.425 | BE30: 16.8 | BF30: 44546.435 | BG30: 16.6 | BH30: 44546.446 | BI30: 17.2 | BJ30: 44546.456 | BK30: 17.2 | BL30: 44546.467 | BM30: 16.4 | BN30: 44546.477 | BO30: 16.5 | BP30: 44546.488 | BQ30: 17.4 | BR30: 44546.498 | BS30: 17.9 | BT30: 44546.508 | BU30: 17.8 | BW30: {=INDEX($AC30:$BU30, 2*(COLUMN(BV30)-COLUMN($BV30))+1)} -> 14.4 | BX30: {=INDEX($AC30:$BU30, 2*(COLUMN(BW30)-COLUMN($BV30))+1)} -> 16.4 | BY30: {=INDEX($AC30:$BU30, 2*(COLUMN(BX30)-COLUMN($BV30))+1)} -> 18.8 | BZ30: {=INDEX($AC30:$BU30, 2*(COLUMN(BY30)-COLUMN($BV30))+1)} -> 21.1 | CA30: {=INDEX($AC30:$BU30, 2*(COLUMN(BZ30)-COLUMN($BV30))+1)} -> 23.1 | CB30: {=INDEX($AC30:$BU30, 2*(COLUMN(CA30)-COLUMN($BV30))+1)} -> 24.3 | CC30: {=INDEX($AC30:$BU30, 2*(COLUMN(CB30)-COLUMN($BV30))+1)} -> 25 | CD30: {=INDEX($AC30:$BU30, 2*(COLUMN(CC30)-COLUMN($BV30))+1)} -> 25.3 | ... CS30: {=INDEX($AC30:$BU30, 2*(COLUMN(CR30)-COLUMN($BV30))+1)} -> 17.8
A31: 251777 | B31: 正常 | D31: 45387 | E31: 45387.292 | F31: 9.9879559 | G31: 11.75 | H31: 11.626667 | I31: 11.6 | J31: 11.88 | K31: 11.62 | L31: 10.666667 | M31: 10.04 | N31: 10.186667 | O31: 10.106667 | P31: 9.3533333 | Q31: 8.3666667 | R31: 7.9266667 | S31: 7.9 | T31: 12 | U31: 1 | V31: 0.25 | W31: -0.022905028 | X31: 1847.975 | Y31: 0 | Z31: 1847.975 | AA31: -1847.975 | AB31: 45387.272 | AC31: 11.7 | AD31: 45387.282 | AE31: 11.8 | AF31: 45387.292 | AG31: 12 | AH31: 45387.303 | AI31: 11.6 | AJ31: 45387.313 | AK31: 11.6 | AL31: 45387.324 | AM31: 11.9 | AN31: 45387.334 | AO31: 11.6 | AP31: 45387.344 | AQ31: 10.6 | AR31: 45387.355 | AS31: 10 | AT31: 45387.365 | AU31: 10.2 | AV31: 45387.376 | AW31: 10.1 | AX31: 45387.386 | AY31: 9.3 | AZ31: 45387.397 | BA31: 8.3 | BB31: 45387.407 | BC31: 7.9 | BD31: 45387.417 | BE31: 7.9 | BF31: 45387.428 | BG31: 7.2 | BH31: 45387.438 | BI31: 6.6 | BJ31: 45387.449 | BK31: 6.5 | BL31: 45387.459 | BM31: 6.7 | BN31: 45387.469 | BO31: 6.7 | BP31: 45387.48 | BQ31: 6.6 | BR31: 45387.49 | BS31: 6.6 | BT31: 45387.501 | BU31: 6.9 | BW31: {=INDEX($AC31:$BU31, 2*(COLUMN(BV31)-COLUMN($BV31))+1)} -> 11.7 | BX31: {=INDEX($AC31:$BU31, 2*(COLUMN(BW31)-COLUMN($BV31))+1)} -> 11.8 | BY31: {=INDEX($AC31:$BU31, 2*(COLUMN(BX31)-COLUMN($BV31))+1)} -> 12 | BZ31: {=INDEX($AC31:$BU31, 2*(COLUMN(BY31)-COLUMN($BV31))+1)} -> 11.6 | CA31: {=INDEX($AC31:$BU31, 2*(COLUMN(BZ31)-COLUMN($BV31))+1)} -> 11.6 | CB31: {=INDEX($AC31:$BU31, 2*(COLUMN(CA31)-COLUMN($BV31))+1)} -> 11.9 | CC31: {=INDEX($AC31:$BU31, 2*(COLUMN(CB31)-COLUMN($BV31))+1)} -> 11.6 | CD31: {=INDEX($AC31:$BU31, 2*(COLUMN(CC31)-COLUMN($BV31))+1)} -> 10.6 | ... CS31: {=INDEX($AC31:$BU31, 2*(COLUMN(CR31)-COLUMN($BV31))+1)} -> 6.9
A32: 252375 | B32: 正常 | D32: 45163 | E32: 45163.292 | F32: 9.87 | G32: 7.75 | H32: 7.94 | I32: 7.82 | J32: 7.4 | K32: 6.66 | L32: 6.26 | M32: 5.8 | N32: 5.06 | O32: 4.18 | P32: 3.6 | Q32: 3.26 | R32: 3.12 | S32: 3.1 | T32: 8.1 | U32: 3 | V32: 0.11666667 | W32: -0.028248588 | X32: 997.875 | Y32: 0 | Z32: 997.875 | AA32: -997.875 | AB32: 45163.273 | AC32: 7.6 | AD32: 45163.283 | AE32: 7.9 | AF32: 45163.294 | AG32: 8.1 | AH32: 45163.304 | AI32: 7.9 | AJ32: 45163.315 | AK32: 7.8 | AL32: 45163.325 | AM32: 7.3 | AN32: 45163.335 | AO32: 6.5 | AP32: 45163.346 | AQ32: 6.2 | AR32: 45163.356 | AS32: 5.7 | AT32: 45163.367 | AU32: 4.9 | AV32: 45163.377 | AW32: 4 | AX32: 45163.387 | AY32: 3.5 | AZ32: 45163.398 | BA32: 3.2 | BB32: 45163.408 | BC32: 3.1 | BD32: 45163.419 | BE32: 3 | BF32: 45163.429 | BG32: 2.8 | BH32: 45163.44 | BI32: 2.8 | BJ32: 45163.45 | BK32: 3.2 | BL32: 45163.46 | BM32: 3.6 | BN32: 45163.471 | BO32: 3.7 | BP32: 45163.481 | BQ32: 3.8 | BR32: 45163.492 | BS32: 3.8 | BT32: 45163.502 | BU32: 3.8 | BW32: {=INDEX($AC32:$BU32, 2*(COLUMN(BV32)-COLUMN($BV32))+1)} -> 7.6 | BX32: {=INDEX($AC32:$BU32, 2*(COLUMN(BW32)-COLUMN($BV32))+1)} -> 7.9 | BY32: {=INDEX($AC32:$BU32, 2*(COLUMN(BX32)-COLUMN($BV32))+1)} -> 8.1 | BZ32: {=INDEX($AC32:$BU32, 2*(COLUMN(BY32)-COLUMN($BV32))+1)} -> 7.9 | CA32: {=INDEX($AC32:$BU32, 2*(COLUMN(BZ32)-COLUMN($BV32))+1)} -> 7.8 | CB32: {=INDEX($AC32:$BU32, 2*(COLUMN(CA32)-COLUMN($BV32))+1)} -> 7.3 | CC32: {=INDEX($AC32:$BU32, 2*(COLUMN(CB32)-COLUMN($BV32))+1)} -> 6.5 | CD32: {=INDEX($AC32:$BU32, 2*(COLUMN(CC32)-COLUMN($BV32))+1)} -> 6.2 | ... CS32: {=INDEX($AC32:$BU32, 2*(COLUMN(CR32)-COLUMN($BV32))+1)} -> 3.8
A33: 254965 | B33: 正常 | D33: 45272 | E33: 45272.292 | F33: 7.98 | G33: 9.4 | H33: 9.28 | I33: 8.98 | J33: 8.6733333 | K33: 8.2666667 | L33: 7.7666667 | M33: 7.2733333 | N33: 6.88 | O33: 6.5866667 | P33: 6.4266667 | Q33: 6.8533333 | R33: 7.62 | S33: 7.9 | T33: 9.3 | U33: 14 | V33: -0.0071428571 | W33: -0.0084337349 | X33: 1398.85 | Y33: 0 | Z33: 1398.85 | AA33: -1398.85 | AB33: 45272.281 | AC33: 9.4 | AD33: 45272.291 | AE33: 9.4 | AF33: 45272.301 | AG33: 9.3 | AH33: 45272.312 | AI33: 9 | AJ33: 45272.322 | AK33: 8.7 | AL33: 45272.333 | AM33: 8.3 | AN33: 45272.343 | AO33: 7.8 | AP33: 45272.353 | AQ33: 7.3 | AR33: 45272.364 | AS33: 6.9 | AT33: 45272.374 | AU33: 6.6 | AV33: 45272.385 | AW33: 6.4 | AX33: 45272.395 | AY33: 6.8 | AZ33: 45272.406 | BA33: 7.6 | BB33: 45272.416 | BC33: 7.9 | BD33: 45272.426 | BE33: 7.8 | BF33: 45272.437 | BG33: 7.8 | BH33: 45272.447 | BI33: 7.8 | BJ33: 45272.458 | BK33: 7.9 | BL33: 45272.468 | BM33: 8.3 | BN33: 45272.478 | BO33: 8.8 | BP33: 45272.489 | BQ33: 9.2 | BR33: 45272.499 | BS33: 9.4 | BT33: 45272.51 | BU33: 9.3 | BW33: {=INDEX($AC33:$BU33, 2*(COLUMN(BV33)-COLUMN($BV33))+1)} -> 9.4 | BX33: {=INDEX($AC33:$BU33, 2*(COLUMN(BW33)-COLUMN($BV33))+1)} -> 9.4 | BY33: {=INDEX($AC33:$BU33, 2*(COLUMN(BX33)-COLUMN($BV33))+1)} -> 9.3 | BZ33: {=INDEX($AC33:$BU33, 2*(COLUMN(BY33)-COLUMN($BV33))+1)} -> 9 | CA33: {=INDEX($AC33:$BU33, 2*(COLUMN(BZ33)-COLUMN($BV33))+1)} -> 8.7 | CB33: {=INDEX($AC33:$BU33, 2*(COLUMN(CA33)-COLUMN($BV33))+1)} -> 8.3 | CC33: {=INDEX($AC33:$BU33, 2*(COLUMN(CB33)-COLUMN($BV33))+1)} -> 7.8 | CD33: {=INDEX($AC33:$BU33, 2*(COLUMN(CC33)-COLUMN($BV33))+1)} -> 7.3 | ... CS33: {=INDEX($AC33:$BU33, 2*(COLUMN(CR33)-COLUMN($BV33))+1)} -> 9.3
A34: 264903 | B34: 正常 | D34: 45155 | E34: 45155.292 | F34: 11.86 | G34: 10.25 | H34: 9.5266667 | I34: 8.8066667 | J34: 8.2666667 | K34: 8.1133333 | L34: 7.9266667 | M34: 7.8133333 | N34: 7.8 | O34: 7.7133333 | P34: 7.3533333 | Q34: 7.4733333 | R34: 8.4533333 | S34: 8.6 | T34: 9.7 | U34: 2 | V34: -0.275 | W34: -0.0061797753 | X34: 1480.075 | Y34: 0 | Z34: 1480.075 | AA34: -1480.075 | AB34: 45155.272 | AC34: 10.6 | AD34: 45155.283 | AE34: 9.9 | AF34: 45155.293 | AG34: 9.7 | AH34: 45155.303 | AI34: 9.5 | AJ34: 45155.314 | AK34: 8.7 | AL34: 45155.324 | AM34: 8.2 | AN34: 45155.335 | AO34: 8.1 | AP34: 45155.345 | AQ34: 7.9 | AR34: 45155.356 | AS34: 7.8 | AT34: 45155.366 | AU34: 7.8 | AV34: 45155.376 | AW34: 7.7 | AX34: 45155.387 | AY34: 7.3 | AZ34: 45155.397 | BA34: 7.5 | BB34: 45155.408 | BC34: 8.6 | BD34: 45155.418 | BE34: 9.6 | BF34: 45155.428 | BG34: 10.2 | BH34: 45155.439 | BI34: 10.4 | BJ34: 45155.449 | BK34: 10.2 | BL34: 45155.46 | BM34: 10.3 | BN34: 45155.47 | BO34: 10.2 | BP34: 45155.481 | BQ34: 9.7 | BR34: 45155.491 | BS34: 9.7 | BT34: 45155.501 | BU34: 10.1 | BW34: {=INDEX($AC34:$BU34, 2*(COLUMN(BV34)-COLUMN($BV34))+1)} -> 10.6 | BX34: {=INDEX($AC34:$BU34, 2*(COLUMN(BW34)-COLUMN($BV34))+1)} -> 9.9 | BY34: {=INDEX($AC34:$BU34, 2*(COLUMN(BX34)-COLUMN($BV34))+1)} -> 9.7 | BZ34: {=INDEX($AC34:$BU34, 2*(COLUMN(BY34)-COLUMN($BV34))+1)} -> 9.5 | CA34: {=INDEX($AC34:$BU34, 2*(COLUMN(BZ34)-COLUMN($BV34))+1)} -> 8.7 | CB34: {=INDEX($AC34:$BU34, 2*(COLUMN(CA34)-COLUMN($BV34))+1)} -> 8.2 | CC34: {=INDEX($AC34:$BU34, 2*(COLUMN(CB34)-COLUMN($BV34))+1)} -> 8.1 | CD34: {=INDEX($AC34:$BU34, 2*(COLUMN(CC34)-COLUMN($BV34))+1)} -> 7.9 | ... CS34: {=INDEX($AC34:$BU34, 2*(COLUMN(CR34)-COLUMN($BV34))+1)} -> 10.1
A35: 265790 | B35: 正常 | D35: 45107 | E35: 45107.292 | F35: 9.7026521 | G35: 9.85 | H35: 9.2133333 | I35: 8.7666667 | J35: 8.2666667 | K35: 8.5466667 | L35: 9.9866667 | M35: 11.933333 | N35: 13.5 | O35: 13.353333 | P35: 11.826667 | Q35: 10.646667 | R35: 10.76 | S35: 10.8 | T35: 13.7 | U35: 107 | V35: 0.035981308 | W35: -0.039726027 | X35: 1906.875 | Y35: 0 | Z35: 1906.875 | AA35: -1906.875 | AB35: 45107.272 | AC35: 10 | AD35: 45107.283 | AE35: 9.7 | AF35: 45107.293 | AG35: 9.3 | AH35: 45107.303 | AI35: 9.2 | AJ35: 45107.314 | AK35: 8.7 | AL35: 45107.324 | AM35: 8.2 | AN35: 45107.335 | AO35: 8.6 | AP35: 45107.345 | AQ35: 10.2 | AR35: 45107.356 | AS35: 12.2 | AT35: 45107.366 | AU35: 13.7 | AV35: 45107.376 | AW35: 13.3 | AX35: 45107.387 | AY35: 11.6 | AZ35: 45107.397 | BA35: 10.5 | BB35: 45107.408 | BC35: 10.8 | BD35: 45107.418 | BE35: 11.2 | BF35: 45107.428 | BG35: 11.3 | BH35: 45107.439 | BI35: 10.8 | BJ35: 45107.449 | BK35: 9.4 | BL35: 45107.46 | BM35: 8.2 | BN35: 45107.47 | BO35: 7.2 | BP35: 45107.481 | BQ35: 6.4 | BR35: 45107.491 | BS35: 6 | BT35: 45107.501 | BU35: 6.3 | BW35: {=INDEX($AC35:$BU35, 2*(COLUMN(BV35)-COLUMN($BV35))+1)} -> 10 | BX35: {=INDEX($AC35:$BU35, 2*(COLUMN(BW35)-COLUMN($BV35))+1)} -> 9.7 | BY35: {=INDEX($AC35:$BU35, 2*(COLUMN(BX35)-COLUMN($BV35))+1)} -> 9.3 | BZ35: {=INDEX($AC35:$BU35, 2*(COLUMN(BY35)-COLUMN($BV35))+1)} -> 9.2 | CA35: {=INDEX($AC35:$BU35, 2*(COLUMN(BZ35)-COLUMN($BV35))+1)} -> 8.7 | CB35: {=INDEX($AC35:$BU35, 2*(COLUMN(CA35)-COLUMN($BV35))+1)} -> 8.2 | CC35: {=INDEX($AC35:$BU35, 2*(COLUMN(CB35)-COLUMN($BV35))+1)} -> 8.6 | CD35: {=INDEX($AC35:$BU35, 2*(COLUMN(CC35)-COLUMN($BV35))+1)} -> 10.2 | ... CS35: {=INDEX($AC35:$BU35, 2*(COLUMN(CR35)-COLUMN($BV35))+1)} -> 6.3
